Workbook
Name DataRef: Listas!$F$2

Sheet LEIA-ME
B1: Base de dados do planejamento trimestral
B2: Exemplo com dados fictícios, 4º trimestre de 2026. Serve para conhecer o preenchimento e testar o painel.
A4: As abas
A5: Aba | B5: Para que serve | C5: Quem preenche | D5: Quando
A6: Frentes | B6: As frentes do trimestre, com as datas da base e do reprogramado e a unidade de medição. Alimenta o Gantt. | C6: Cronograma e engenheiro | D6: Na virada do mês
A7: Restrições | B7: Uma linha por restrição, com tipo, responsável, prazo, impactos e observação. Situação calculada. | C7: Engenheiro | D7: Sempre que surgir ou mudar uma restrição
A8: Previsibilidade | B8: Quantidade e equipe, previstas e reais, por frente e por semana (e por local, se quiser detalhar). | C8: Engenheiro | D8: Prevê as próximas semanas e fecha a semana que passou
A9: Planos de ação | B9: As ações que a obra está desenvolvendo, com responsável, prazo e status. | C9: Engenheiro | D9: Sempre que houver uma ação nova
A10: Cronograma | B10: Resumo do cronograma para o previsto x realizado: datas, atividades atrasadas e a curva mensal. | C10: Leitor do cronograma | D10: Quando o cronograma for atualizado
A11: Listas | B11: Data de referência e as listas das caixas de seleção. | C11: Planejamento | D11: Quando algo mudar
A14: Cores
A15: Célula branca | B15: Campo de preenchimento, com lista ou validação quando aplicável.
A16: Célula azul | B16: Fórmula. Não preencher.
A17: Cabeçalho escuro | B17: Coluna de preenchimento.
A18: Cabeçalho azul | B18: Coluna de fórmula.
A20: Regras de cálculo
A21: Situação da restrição: resolvida quando tem Prazo resolvido; vencida quando não tem e o Prazo limite é anterior à data de referência; no prazo nas demais.
A22: Produtividade esperada é a quantidade prevista dividida pela equipe prevista da semana. Produtividade real é a quantidade executada dividida pela equipe real. Índice da semana é a real dividida pela esperada: boa a partir de 95%, regular de 85% a 95% e ruim abaixo de 85%.
A23: Previsibilidade com locais: se uma frente tem linhas por local na semana, os totais da frente são a soma dos locais. Sem linhas por local, vale a linha da frente. A premissa do engenheiro vai na Observação da linha da frente da primeira semana de previsão.
A24: Semana: use a data da segunda-feira. A semana pertence ao mês em que cai a maioria dos dias úteis.

Sheet Frentes
A1: Frentes de serviço do trimestre
A2: Frentes de serviço do trimestre, com unidade de medição e período.
A4: FRENTE | B4: UNIDADE | C4: INÍCIO BASE | D4: TÉRMINO BASE | E4: INÍCIO REPROG. | F4: TÉRMINO REPROG. | G4: LOCAIS | H4: RESTRIÇÕES TOTAIS | I4: RESTRIÇÕES REMOVIDAS | J4: RESTRIÇÕES PENDENTES
A5: Fachada e reboco externo | B5: m² | C5: 46183 | D5: 46659 | E5: 46265 | F5: 46392 | G5: Torre 1, Torre 2, Torre 3, Área de Lazer, Térreo | H5: =IF(A5="","",COUNTIF('Restrições'!$A$5:$A$604,A5)) -> 6 | I5: =IF(A5="","",COUNTIFS('Restrições'!$A$5:$A$604,A5,'Restrições'!$G$5:$G$604,"<>")) -> 2 | J5: =IF(A5="","",H5-I5) -> 4
A6: Regularização de escadas | B6: lance | C6: 46174 | D6: 46295 | E6: 46296 | F6: 46407 | G6: SS2, Térreo, Área de Lazer, Torre 1, Torre 3 | H6: =IF(A6="","",COUNTIF('Restrições'!$A$5:$A$604,A6)) -> 2 | I6: =IF(A6="","",COUNTIFS('Restrições'!$A$5:$A$604,A6,'Restrições'!$G$5:$G$604,"<>")) -> 1 | J6: =IF(A6="","",H6-I6) -> 1
A7: Instalações elétricas | B7: pontos | C7: 46175 | D7: 46538 | E7: 46296 | F7: 46379 | G7: Torre 1, Torre 3, SS1, Área de Lazer, Térreo | H7: =IF(A7="","",COUNTIF('Restrições'!$A$5:$A$604,A7)) -> 4 | I7: =IF(A7="","",COUNTIFS('Restrições'!$A$5:$A$604,A7,'Restrições'!$G$5:$G$604,"<>")) -> 1 | J7: =IF(A7="","",H7-I7) -> 3
A8: Alvenaria e shafts | B8: m² | C8: 46204 | D8: 46524 | E8: 46297 | F8: 46358 | G8: Torre 1, Torre 3, SS1, SS2, Área de Lazer, Térreo, Torre 2 | H8: =IF(A8="","",COUNTIF('Restrições'!$A$5:$A$604,A8)) -> 5 | I8: =IF(A8="","",COUNTIFS('Restrições'!$A$5:$A$604,A8,'Restrições'!$G$5:$G$604,"<>")) -> 3 | J8: =IF(A8="","",H8-I8) -> 2
A9: Forro e tratamento de teto | B9: m² | C9: 46237 | D9: 46549 | E9: 46300 | F9: 46379 | G9: Torre 1, Torre 3, SS1, SS2, Térreo | H9: =IF(A9="","",COUNTIF('Restrições'!$A$5:$A$604,A9)) -> 3 | I9: =IF(A9="","",COUNTIFS('Restrições'!$A$5:$A$604,A9,'Restrições'!$G$5:$G$604,"<>")) -> 0 | J9: =IF(A9="","",H9-I9) -> 3
A10: Fechamento da cremalheira | B10: pav. | C10: 46626 | D10: 46658 | E10: 46303 | F10: 46379 | G10: Térreo, SS2, Torre 1, Torre 2 | H10: =IF(A10="","",COUNTIF('Restrições'!$A$5:$A$604,A10)) -> 3 | I10: =IF(A10="","",COUNTIFS('Restrições'!$A$5:$A$604,A10,'Restrições'!$G$5:$G$604,"<>")) -> 1 | J10: =IF(A10="","",H10-I10) -> 2
A11: Impermeabilização | B11: m² | C11: 46189 | D11: 46542 | E11: 46303 | F11: 46379 | G11: Torre 1, Torre 2, Torre 3, Área de Lazer, Térreo | H11: =IF(A11="","",COUNTIF('Restrições'!$A$5:$A$604,A11)) -> 5 | I11: =IF(A11="","",COUNTIFS('Restrições'!$A$5:$A$604,A11,'Restrições'!$G$5:$G$604,"<>")) -> 2 | J11: =IF(A11="","",H11-I11) -> 3
A12: Contrapiso e pavimentação | B12: m² | C12: 46182 | D12: 46469 | E12: 46304 | F12: 46391 | G12: Torre 1, Torre 2, Área de Lazer, Térreo, Torre 3 | H12: =IF(A12="","",COUNTIF('Restrições'!$A$5:$A$604,A12)) -> 3 | I12: =IF(A12="","",COUNTIFS('Restrições'!$A$5:$A$604,A12,'Restrições'!$G$5:$G$604,"<>")) -> 1 | J12: =IF(A12="","",H12-I12) -> 2
A13: Reboco interno | B13: m² | C13: 46206 | D13: 46317 | E13: 46311 | F13: 46356 | G13: Torre 3, Térreo, Torre 1, Torre 2, Área de Lazer | H13: =IF(A13="","",COUNTIF('Restrições'!$A$5:$A$604,A13)) -> 3 | I13: =IF(A13="","",COUNTIFS('Restrições'!$A$5:$A$604,A13,'Restrições'!$G$5:$G$604,"<>")) -> 2 | J13: =IF(A13="","",H13-I13) -> 1
A14: Esquadrias | B14: un | C14: 46202 | D14: 46449 | E14: 46318 | F14: 46379 | G14: Torre 1, Torre 3, Térreo | H14: =IF(A14="","",COUNTIF('Restrições'!$A$5:$A$604,A14)) -> 4 | I14: =IF(A14="","",COUNTIFS('Restrições'!$A$5:$A$604,A14,'Restrições'!$G$5:$G$604,"<>")) -> 1 | J14: =IF(A14="","",H14-I14) -> 3
A15: Instalações hidráulicas | B15: pontos | C15: 46181 | D15: 46462 | E15: 46328 | F15: 46379 | G15: Torre 3, SS1, SS2, Térreo, Área de Lazer | H15: =IF(A15="","",COUNTIF('Restrições'!$A$5:$A$604,A15)) -> 5 | I15: =IF(A15="","",COUNTIFS('Restrições'!$A$5:$A$604,A15,'Restrições'!$G$5:$G$604,"<>")) -> 2 | J15: =IF(A15="","",H15-I15) -> 3
A16: Estruturas remanescentes (piscina e marquise) | B16: m³ | C16: 46237 | D16: 46261 | E16: 46330 | F16: 46353 | G16: Área de Lazer, Térreo | H16: =IF(A16="","",COUNTIF('Restrições'!$A$5:$A$604,A16)) -> 4 | I16: =IF(A16="","",COUNTIFS('Restrições'!$A$5:$A$604,A16,'Restrições'!$G$5:$G$604,"<>")) -> 2 | J16: =IF(A16="","",H16-I16) -> 2
H17: =IF(A17="","",COUNTIF('Restrições'!$A$5:$A$604,A17)) | I17: =IF(A17="","",COUNTIFS('Restrições'!$A$5:$A$604,A17,'Restrições'!$G$5:$G$604,"<>")) | J17: =IF(A17="","",H17-I17)
H18: =IF(A18="","",COUNTIF('Restrições'!$A$5:$A$604,A18)) | I18: =IF(A18="","",COUNTIFS('Restrições'!$A$5:$A$604,A18,'Restrições'!$G$5:$G$604,"<>")) | J18: =IF(A18="","",H18-I18)
H19: =IF(A19="","",COUNTIF('Restrições'!$A$5:$A$604,A19)) | I19: =IF(A19="","",COUNTIFS('Restrições'!$A$5:$A$604,A19,'Restrições'!$G$5:$G$604,"<>")) | J19: =IF(A19="","",H19-I19)
H20: =IF(A20="","",COUNTIF('Restrições'!$A$5:$A$604,A20)) | I20: =IF(A20="","",COUNTIFS('Restrições'!$A$5:$A$604,A20,'Restrições'!$G$5:$G$604,"<>")) | J20: =IF(A20="","",H20-I20)
H21: =IF(A21="","",COUNTIF('Restrições'!$A$5:$A$604,A21)) | I21: =IF(A21="","",COUNTIFS('Restrições'!$A$5:$A$604,A21,'Restrições'!$G$5:$G$604,"<>")) | J21: =IF(A21="","",H21-I21)
H22: =IF(A22="","",COUNTIF('Restrições'!$A$5:$A$604,A22)) | I22: =IF(A22="","",COUNTIFS('Restrições'!$A$5:$A$604,A22,'Restrições'!$G$5:$G$604,"<>")) | J22: =IF(A22="","",H22-I22)
H23: =IF(A23="","",COUNTIF('Restrições'!$A$5:$A$604,A23)) | I23: =IF(A23="","",COUNTIFS('Restrições'!$A$5:$A$604,A23,'Restrições'!$G$5:$G$604,"<>")) | J23: =IF(A23="","",H23-I23)
H24: =IF(A24="","",COUNTIF('Restrições'!$A$5:$A$604,A24)) | I24: =IF(A24="","",COUNTIFS('Restrições'!$A$5:$A$604,A24,'Restrições'!$G$5:$G$604,"<>")) | J24: =IF(A24="","",H24-I24)
H25: =IF(A25="","",COUNTIF('Restrições'!$A$5:$A$604,A25)) | I25: =IF(A25="","",COUNTIFS('Restrições'!$A$5:$A$604,A25,'Restrições'!$G$5:$G$604,"<>")) | J25: =IF(A25="","",H25-I25)
H26: =IF(A26="","",COUNTIF('Restrições'!$A$5:$A$604,A26)) | I26: =IF(A26="","",COUNTIFS('Restrições'!$A$5:$A$604,A26,'Restrições'!$G$5:$G$604,"<>")) | J26: =IF(A26="","",H26-I26)
H27: =IF(A27="","",COUNTIF('Restrições'!$A$5:$A$604,A27)) | I27: =IF(A27="","",COUNTIFS('Restrições'!$A$5:$A$604,A27,'Restrições'!$G$5:$G$604,"<>")) | J27: =IF(A27="","",H27-I27)
H28: =IF(A28="","",COUNTIF('Restrições'!$A$5:$A$604,A28)) | I28: =IF(A28="","",COUNTIFS('Restrições'!$A$5:$A$604,A28,'Restrições'!$G$5:$G$604,"<>")) | J28: =IF(A28="","",H28-I28)
... H64: =IF(A64="","",COUNTIF('Restrições'!$A$5:$A$604,A64)) | I64: =IF(A64="","",COUNTIFS('Restrições'!$A$5:$A$604,A64,'Restrições'!$G$5:$G$604,"<>")) | J64: =IF(A64="","",H64-I64)

Sheet Restrições
A1: Restrições
A2: Registro de restrições por frente de serviço.
A4: FRENTE | B4: TIPO DE RESTRIÇÃO | C4: INÍCIO DA ATIVIDADE | D4: DESCRIÇÃO DA RESTRIÇÃO | E4: RESPONSÁVEL | F4: PRAZO LIMITE DA RESTRIÇÃO | G4: PRAZO RESOLVIDO | H4: IMPACTO NO CUSTO | I4: IMPACTO NO PRAZO | J4: OBSERVAÇÃO | K4: SITUAÇÃO
A5: Fachada e reboco externo | B5: Mão de obra | C5: 46265 | D5: Equipe adicional ainda não mobilizada | E5: Contratos | F5: 46289 | G5: 46302 | H5: Médio | I5: Baixo | K5: =IF(A5="","",IF(G5<>"","Resolvida",IF(F5<DataRef,"Vencida","No prazo"))) -> Resolvida
A6: Fachada e reboco externo | B6: Predecessora | C6: 46265 | D6: Frente anterior com atraso | E6: Eng. de obra | F6: 46290 | G6: 46293 | H6: Baixo | I6: Alto | K6: =IF(A6="","",IF(G6<>"","Resolvida",IF(F6<DataRef,"Vencida","No prazo"))) -> Resolvida
A7: Fachada e reboco externo | B7: Segurança | C7: 46265 | D7: Projeto de proteção coletiva sem aprovação | E7: SESMT | F7: 46301 | H7: Alto | I7: Médio | J7: Documentação em conferência | K7: =IF(A7="","",IF(G7<>"","Resolvida",IF(F7<DataRef,"Vencida","No prazo"))) -> Vencida
A8: Fachada e reboco externo | B8: Equipamentos | C8: 46265 | D8: Balancins sem cotação fechada | E8: Suprimentos | F8: 46316 | H8: Baixo | I8: Médio | J8: Dependente de decisão da diretoria | K8: =IF(A8="","",IF(G8<>"","Resolvida",IF(F8<DataRef,"Vencida","No prazo"))) -> No prazo
A9: Fachada e reboco externo | B9: Material | C9: 46265 | D9: Argamassa de revestimento recebido apenas em parte | E9: Compras | F9: 46337 | H9: Médio | I9: Médio | J9: Em negociação, previsão para a próxima semana | K9: =IF(A9="","",IF(G9<>"","Resolvida",IF(F9<DataRef,"Vencida","No prazo"))) -> No prazo
A10: Fachada e reboco externo | B10: Definição/Projeto | C10: 46265 | D10: Detalhe de juntas da fachada sem aprovação | E10: Diretoria | F10: 46346 | H10: Médio | I10: Médio | K10: =IF(A10="","",IF(G10<>"","Resolvida",IF(F10<DataRef,"Vencida","No prazo"))) -> No prazo
A11: Regularização de escadas | B11: Equipamentos | C11: 46296 | D11: Betoneira sem cotação fechada | E11: Eng. de obra | F11: 46285 | G11: 46283 | H11: Baixo | I11: Médio | J11: Contrato assinado e equipe mobilizada | K11: =IF(A11="","",IF(G11<>"","Resolvida",IF(F11<DataRef,"Vencida","No prazo"))) -> Resolvida
A12: Instalações elétricas | B12: Equipamentos | C12: 46296 | D12: Locação de plataforma elevatória aguardando aprovação | E12: Suprimentos | F12: 46299 | H12: Alto | I12: Baixo | K12: =IF(A12="","",IF(G12<>"","Resolvida",IF(F12<DataRef,"Vencida","No prazo"))) -> Vencida
A13: Instalações elétricas | B13: Mão de obra | C13: 46296 | D13: Aditivo da equipe sem aprovação | E13: RH da obra | F13: 46302 | G13: 46301 | H13: Alto | I13: Médio | J13: Resolvido e conferido em obra | K13: =IF(A13="","",IF(G13<>"","Resolvida",IF(F13<DataRef,"Vencida","No prazo"))) -> Resolvida
A14: Instalações elétricas | B14: Segurança | C14: 46296 | D14: Projeto de proteção coletiva sem aprovação | E14: SESMT | F14: 46319 | H14: Alto | I14: Médio | J14: Documentação em conferência | K14: =IF(A14="","",IF(G14<>"","Resolvida",IF(F14<DataRef,"Vencida","No prazo"))) -> No prazo
A15: Instalações elétricas | B15: Material | C15: 46296 | D15: Cabos e eletrodutos recebido apenas em parte | E15: Compras | F15: 46324 | H15: Alto | I15: Baixo | K15: =IF(A15="","",IF(G15<>"","Resolvida",IF(F15<DataRef,"Vencida","No prazo"))) -> No prazo
A16: Regularização de escadas | B16: Definição/Projeto | C16: 46296 | D16: Detalhe do nariz dos degraus aguardando o cliente | E16: Projetos | F16: 46334 | H16: Médio | I16: Alto | J16: Cotações em análise | K16: =IF(A16="","",IF(G16<>"","Resolvida",IF(F16<DataRef,"Vencida","No prazo"))) -> No prazo
A17: Alvenaria e shafts | B17: Material | C17: 46297 | D17: Blocos e perfis de shaft com entrega atrasada | E17: Compras | F17: 46291 | G17: 46300 | H17: Alto | I17: Médio | J17: Resolvido e conferido em obra | K17: =IF(A17="","",IF(G17<>"","Resolvida",IF(F17<DataRef,"Vencida","No prazo"))) -> Resolvida
A18: Alvenaria e shafts | B18: Mão de obra | C18: 46297 | D18: Aditivo da equipe sem aprovação | E18: RH da obra | F18: 46296 | H18: Alto | I18: Baixo | K18: =IF(A18="","",IF(G18<>"","Resolvida",IF(F18<DataRef,"Vencida","No prazo"))) -> Vencida
A19: Alvenaria e shafts | B19: Segurança | C19: 46297 | D19: Laudo da linha de vida pendente | E19: SESMT | F19: 46297 | G19: 46295 | H19: Médio | I19: Baixo | J19: Contrato assinado e equipe mobilizada | K19: =IF(A19="","",IF(G19<>"","Resolvida",IF(F19<DataRef,"Vencida","No prazo"))) -> Resolvida
A20: Alvenaria e shafts | B20: Definição/Projeto | C20: 46297 | D20: Paginação da alvenaria aguardando o cliente | E20: Projetos | F20: 46297 | G20: 46295 | H20: Alto | I20: Alto | J20: Material recebido e armazenado | K20: =IF(A20="","",IF(G20<>"","Resolvida",IF(F20<DataRef,"Vencida","No prazo"))) -> Resolvida
A21: Alvenaria e shafts | B21: Predecessora | C21: 46297 | D21: Frente anterior com atraso | E21: Planejamento | F21: 46306 | H21: Médio | I21: Médio | J21: Dependente de decisão da diretoria | K21: =IF(A21="","",IF(G21<>"","Resolvida",IF(F21<DataRef,"Vencida","No prazo"))) -> No prazo
A22: Forro e tratamento de teto | B22: Predecessora | C22: 46300 | D22: Liberação da frente anterior pendente | E22: Planejamento | F22: 46306 | H22: Alto | I22: Alto | J22: Cotações em análise | K22: =IF(A22="","",IF(G22<>"","Resolvida",IF(F22<DataRef,"Vencida","No prazo"))) -> No prazo
A23: Forro e tratamento de teto | B23: Definição/Projeto | C23: 46300 | D23: Detalhe de forro aguardando o cliente | E23: Diretoria | F23: 46312 | H23: Médio | I23: Médio | K23: =IF(A23="","",IF(G23<>"","Resolvida",IF(F23<DataRef,"Vencida","No prazo"))) -> No prazo
A24: Forro e tratamento de teto | B24: Equipamentos | C24: 46300 | D24: Andaimes sem cotação fechada | E24: Eng. de obra | F24: 46313 | H24: Alto | I24: Alto | J24: Cotações em análise | K24: =IF(A24="","",IF(G24<>"","Resolvida",IF(F24<DataRef,"Vencida","No prazo"))) -> No prazo
A25: Impermeabilização | B25: Definição/Projeto | C25: 46303 | D25: Detalhamento de ralos e soleiras aguardando o cliente | E25: Diretoria | F25: 46292 | G25: 46299 | H25: Baixo | I25: Alto | J25: Resolvido e conferido em obra | K25: =IF(A25="","",IF(G25<>"","Resolvida",IF(F25<DataRef,"Vencida","No prazo"))) -> Resolvida
A26: Fechamento da cremalheira | B26: Segurança | C26: 46303 | D26: Laudo da linha de vida pendente | E26: SESMT | F26: 46296 | G26: 46295 | H26: Alto | I26: Médio | J26: Material recebido e armazenado | K26: =IF(A26="","",IF(G26<>"","Resolvida",IF(F26<DataRef,"Vencida","No prazo"))) -> Resolvida
A27: Fechamento da cremalheira | B27: Definição/Projeto | C27: 46303 | D27: Sequência de desmontagem sem aprovação | E27: Diretoria | F27: 46297 | H27: Baixo | I27: Baixo | J27: Cotações em análise | K27: =IF(A27="","",IF(G27<>"","Resolvida",IF(F27<DataRef,"Vencida","No prazo"))) -> Vencida
A28: Impermeabilização | B28: Mão de obra | C28: 46303 | D28: Documentação da equipe pendente | E28: RH da obra | F28: 46303 | G28: 46295 | H28: Médio | I28: Baixo | J28: Material recebido e armazenado | K28: =IF(A28="","",IF(G28<>"","Resolvida",IF(F28<DataRef,"Vencida","No prazo"))) -> Resolvida
A29: Impermeabilização | B29: Segurança | C29: 46303 | D29: Laudo da linha de vida pendente | E29: SESMT | F29: 46310 | H29: Baixo | I29: Baixo | K29: =IF(A29="","",IF(G29<>"","Resolvida",IF(F29<DataRef,"Vencida","No prazo"))) -> No prazo
A30: Impermeabilização | B30: Equipamentos | C30: 46303 | D30: Liberação de maçarico pendente | E30: Eng. de obra | F30: 46328 | H30: Médio | I30: Alto | J30: Aguardando retorno do fornecedor | K30: =IF(A30="","",IF(G30<>"","Resolvida",IF(F30<DataRef,"Vencida","No prazo"))) -> No prazo
A31: Fechamento da cremalheira | B31: Predecessora | C31: 46303 | D31: Liberação da frente anterior pendente | E31: Planejamento | F31: 46331 | H31: Médio | I31: Médio | J31: Aguardando retorno do fornecedor | K31: =IF(A31="","",IF(G31<>"","Resolvida",IF(F31<DataRef,"Vencida","No prazo"))) -> No prazo
A32: Impermeabilização | B32: Predecessora | C32: 46303 | D32: Liberação da frente anterior pendente | E32: Planejamento | F32: 46342 | H32: Baixo | I32: Alto | J32: Dependente de decisão da diretoria | K32: =IF(A32="","",IF(G32<>"","Resolvida",IF(F32<DataRef,"Vencida","No prazo"))) -> No prazo
A33: Contrapiso e pavimentação | B33: Segurança | C33: 46304 | D33: Laudo da linha de vida pendente | E33: SESMT | F33: 46294 | G33: 46295 | H33: Baixo | I33: Médio | J33: Resolvido e conferido em obra | K33: =IF(A33="","",IF(G33<>"","Resolvida",IF(F33<DataRef,"Vencida","No prazo"))) -> Resolvida
A34: Contrapiso e pavimentação | B34: Material | C34: 46304 | D34: Cimento e areia recebido apenas em parte | E34: Suprimentos | F34: 46317 | H34: Baixo | I34: Alto | J34: Em negociação, previsão para a próxima semana | K34: =IF(A34="","",IF(G34<>"","Resolvida",IF(F34<DataRef,"Vencida","No prazo"))) -> No prazo
A35: Contrapiso e pavimentação | B35: Equipamentos | C35: 46304 | D35: Bomba de contrapiso sem cotação fechada | E35: Suprimentos | F35: 46326 | H35: Baixo | I35: Baixo | J35: Documentação em conferência | K35: =IF(A35="","",IF(G35<>"","Resolvida",IF(F35<DataRef,"Vencida","No prazo"))) -> No prazo
A36: Reboco interno | B36: Predecessora | C36: 46311 | D36: Liberação da frente anterior pendente | E36: Eng. de obra | F36: 46290 | G36: 46288 | H36: Alto | I36: Alto | J36: Material recebido e armazenado | K36: =IF(A36="","",IF(G36<>"","Resolvida",IF(F36<DataRef,"Vencida","No prazo"))) -> Resolvida
A37: Reboco interno | B37: Equipamentos | C37: 46311 | D37: Locação de projetora de argamassa aguardando aprovação | E37: Eng. de obra | F37: 46290 | G37: 46298 | H37: Médio | I37: Baixo | J37: Contrato assinado e equipe mobilizada | K37: =IF(A37="","",IF(G37<>"","Resolvida",IF(F37<DataRef,"Vencida","No prazo"))) -> Resolvida
A38: Reboco interno | B38: Mão de obra | C38: 46311 | D38: Aditivo da equipe sem aprovação | E38: Contratos | F38: 46338 | H38: Alto | I38: Médio | K38: =IF(A38="","",IF(G38<>"","Resolvida",IF(F38<DataRef,"Vencida","No prazo"))) -> No prazo
A39: Esquadrias | B39: Definição/Projeto | C39: 46318 | D39: Detalhe de caixilho sem aprovação | E39: Projetos | F39: 46290 | G39: 46287 | H39: Baixo | I39: Baixo | K39: =IF(A39="","",IF(G39<>"","Resolvida",IF(F39<DataRef,"Vencida","No prazo"))) -> Resolvida
A40: Esquadrias | B40: Predecessora | C40: 46318 | D40: Frente anterior com atraso | E40: Eng. de obra | F40: 46295 | H40: Médio | I40: Médio | J40: Cotações em análise | K40: =IF(A40="","",IF(G40<>"","Resolvida",IF(F40<DataRef,"Vencida","No prazo"))) -> Vencida
A41: Esquadrias | B41: Equipamentos | C41: 46318 | D41: Liberação de carrinhos de transporte pendente | E41: Eng. de obra | F41: 46323 | H41: Alto | I41: Médio | J41: Cotações em análise | K41: =IF(A41="","",IF(G41<>"","Resolvida",IF(F41<DataRef,"Vencida","No prazo"))) -> No prazo
...

Sheet Previsibilidade
A1: Previsibilidade semanal
A2: Previsto e realizado semanal por frente de serviço.
A4: SEMANA (SEGUNDA) | B4: FRENTE | C4: LOCAL (OPCIONAL) | D4: UN. | E4: QTD PREVISTA | F4: EQUIPE PREVISTA | G4: QTD EXECUTADA | H4: EQUIPE REAL | I4: OBSERVAÇÃO OU PREMISSA | J4: PRODUTIVIDADE ESPERADA | K4: PRODUTIVIDADE REAL | L4: ÍNDICE DA SEMANA
A5: 46300 | B5: Fachada e reboco externo | C5: Torre 2, Etapa 02 | REBOCO EXTERNO - Fachada | D5: =IF(B5="","",IFERROR(VLOOKUP(B5,Frentes!$A$5:$B$64,2,0),"")) -> m² | E5: 207 | F5: 5 | G5: 114 | H5: 4 | J5: =IF(AND(ISNUMBER(E5),ISNUMBER(F5)),IF(F5>0,E5/F5,""),"") -> 41.4 | K5: =IF(AND(ISNUMBER(G5),ISNUMBER(H5)),IF(H5>0,G5/H5,""),"") -> 28.5 | L5: =IF(AND(ISNUMBER(J5),ISNUMBER(K5)),IF(J5>0,K5/J5,""),"") -> 0.6884058
A6: 46300 | B6: Fachada e reboco externo | C6: Torre 2, Etapa 03 | LIMPEZA + CHAPISCO - Fachada | D6: =IF(B6="","",IFERROR(VLOOKUP(B6,Frentes!$A$5:$B$64,2,0),"")) -> m² | E6: 156 | F6: 3 | G6: 98 | H6: 3 | J6: =IF(AND(ISNUMBER(E6),ISNUMBER(F6)),IF(F6>0,E6/F6,""),"") -> 52 | K6: =IF(AND(ISNUMBER(G6),ISNUMBER(H6)),IF(H6>0,G6/H6,""),"") -> 32.666667 | L6: =IF(AND(ISNUMBER(J6),ISNUMBER(K6)),IF(J6>0,K6/J6,""),"") -> 0.62820513
A7: 46300 | B7: Fachada e reboco externo | C7: Torre 1, Etapa FC | MONTAGEM BALANCINS - FC | D7: =IF(B7="","",IFERROR(VLOOKUP(B7,Frentes!$A$5:$B$64,2,0),"")) -> m² | E7: 79 | F7: 2 | G7: 60 | H7: 2 | J7: =IF(AND(ISNUMBER(E7),ISNUMBER(F7)),IF(F7>0,E7/F7,""),"") -> 39.5 | K7: =IF(AND(ISNUMBER(G7),ISNUMBER(H7)),IF(H7>0,G7/H7,""),"") -> 30 | L7: =IF(AND(ISNUMBER(J7),ISNUMBER(K7)),IF(J7>0,K7/J7,""),"") -> 0.75949367
A8: 46300 | B8: Fachada e reboco externo | C8: Torre 1, Etapa FC | REBOCO EXTERNO - FC | D8: =IF(B8="","",IFERROR(VLOOKUP(B8,Frentes!$A$5:$B$64,2,0),"")) -> m² | E8: 78 | F8: 2 | G8: 56 | H8: 1 | J8: =IF(AND(ISNUMBER(E8),ISNUMBER(F8)),IF(F8>0,E8/F8,""),"") -> 39 | K8: =IF(AND(ISNUMBER(G8),ISNUMBER(H8)),IF(H8>0,G8/H8,""),"") -> 56 | L8: =IF(AND(ISNUMBER(J8),ISNUMBER(K8)),IF(J8>0,K8/J8,""),"") -> 1.4358974
A9: 46300 | B9: Fachada e reboco externo | C9: Outros locais (2) | D9: =IF(B9="","",IFERROR(VLOOKUP(B9,Frentes!$A$5:$B$64,2,0),"")) -> m² | E9: 80 | F9: 2 | G9: 44 | H9: 2 | J9: =IF(AND(ISNUMBER(E9),ISNUMBER(F9)),IF(F9>0,E9/F9,""),"") -> 40 | K9: =IF(AND(ISNUMBER(G9),ISNUMBER(H9)),IF(H9>0,G9/H9,""),"") -> 22 | L9: =IF(AND(ISNUMBER(J9),ISNUMBER(K9)),IF(J9>0,K9/J9,""),"") -> 0.55
A10: 46300 | B10: Regularização de escadas | C10: SS2, Cx. Escada | Regularização Escada | D10: =IF(B10="","",IFERROR(VLOOKUP(B10,Frentes!$A$5:$B$64,2,0),"")) -> lance | E10: 1 | F10: 1 | G10: 1 | H10: 1 | J10: =IF(AND(ISNUMBER(E10),ISNUMBER(F10)),IF(F10>0,E10/F10,""),"") -> 1 | K10: =IF(AND(ISNUMBER(G10),ISNUMBER(H10)),IF(H10>0,G10/H10,""),"") -> 1 | L10: =IF(AND(ISNUMBER(J10),ISNUMBER(K10)),IF(J10>0,K10/J10,""),"") -> 1
A11: 46300 | B11: Regularização de escadas | C11: Térreo, Cx. Escada | Regularização Escada | D11: =IF(B11="","",IFERROR(VLOOKUP(B11,Frentes!$A$5:$B$64,2,0),"")) -> lance | E11: 0 | F11: 1 | G11: 0 | H11: 1 | J11: =IF(AND(ISNUMBER(E11),ISNUMBER(F11)),IF(F11>0,E11/F11,""),"") -> 0 | K11: =IF(AND(ISNUMBER(G11),ISNUMBER(H11)),IF(H11>0,G11/H11,""),"") -> 0 | L11: =IF(AND(ISNUMBER(J11),ISNUMBER(K11)),IF(J11>0,K11/J11,""),"")
A12: 46300 | B12: Regularização de escadas | C12: Área de Lazer, 1º Pav. | Regularização Escada - Cx. Escada | D12: =IF(B12="","",IFERROR(VLOOKUP(B12,Frentes!$A$5:$B$64,2,0),"")) -> lance | E12: 0 | F12: 0 | G12: 0 | H12: 0 | J12: =IF(AND(ISNUMBER(E12),ISNUMBER(F12)),IF(F12>0,E12/F12,""),"") | K12: =IF(AND(ISNUMBER(G12),ISNUMBER(H12)),IF(H12>0,G12/H12,""),"") | L12: =IF(AND(ISNUMBER(J12),ISNUMBER(K12)),IF(J12>0,K12/J12,""),"")
A13: 46300 | B13: Regularização de escadas | C13: Torre 1, 2º Pav. | Regularização Escada - Cx. Escada | D13: =IF(B13="","",IFERROR(VLOOKUP(B13,Frentes!$A$5:$B$64,2,0),"")) -> lance | E13: 0 | F13: 0 | G13: 0 | H13: 0 | J13: =IF(AND(ISNUMBER(E13),ISNUMBER(F13)),IF(F13>0,E13/F13,""),"") | K13: =IF(AND(ISNUMBER(G13),ISNUMBER(H13)),IF(H13>0,G13/H13,""),"") | L13: =IF(AND(ISNUMBER(J13),ISNUMBER(K13)),IF(J13>0,K13/J13,""),"")
A14: 46300 | B14: Regularização de escadas | C14: Outros locais (10) | D14: =IF(B14="","",IFERROR(VLOOKUP(B14,Frentes!$A$5:$B$64,2,0),"")) -> lance | E14: 3 | F14: 4 | G14: 3 | H14: 4 | J14: =IF(AND(ISNUMBER(E14),ISNUMBER(F14)),IF(F14>0,E14/F14,""),"") -> 0.75 | K14: =IF(AND(ISNUMBER(G14),ISNUMBER(H14)),IF(H14>0,G14/H14,""),"") -> 0.75 | L14: =IF(AND(ISNUMBER(J14),ISNUMBER(K14)),IF(J14>0,K14/J14,""),"") -> 1
A15: 46300 | B15: Instalações elétricas | C15: Torre 3, Casa de Máquinas | Instalações Elétricas - CM | D15: =IF(B15="","",IFERROR(VLOOKUP(B15,Frentes!$A$5:$B$64,2,0),"")) -> pontos | E15: 27 | F15: 2 | G15: 22 | H15: 2 | J15: =IF(AND(ISNUMBER(E15),ISNUMBER(F15)),IF(F15>0,E15/F15,""),"") -> 13.5 | K15: =IF(AND(ISNUMBER(G15),ISNUMBER(H15)),IF(H15>0,G15/H15,""),"") -> 11 | L15: =IF(AND(ISNUMBER(J15),ISNUMBER(K15)),IF(J15>0,K15/J15,""),"") -> 0.81481481
A16: 46300 | B16: Instalações elétricas | C16: Torre 1, 12º Pav. | Enfiação de Shaft + Teste Elétrico | D16: =IF(B16="","",IFERROR(VLOOKUP(B16,Frentes!$A$5:$B$64,2,0),"")) -> pontos | E16: 22 | F16: 2 | G16: 19 | H16: 2 | J16: =IF(AND(ISNUMBER(E16),ISNUMBER(F16)),IF(F16>0,E16/F16,""),"") -> 11 | K16: =IF(AND(ISNUMBER(G16),ISNUMBER(H16)),IF(H16>0,G16/H16,""),"") -> 9.5 | L16: =IF(AND(ISNUMBER(J16),ISNUMBER(K16)),IF(J16>0,K16/J16,""),"") -> 0.86363636
... A44: 46300 | B44: Instalações hidráulicas | C44: Torre 3, 16º Pav. | Isolamento Acústico Hidráulico | D44: =IF(B44="","",IFERROR(VLOOKUP(B44,Frentes!$A$5:$B$64,2,0),"")) -> pontos | E44: 9 | F44: 1 | G44: 6 | H44: 1 | J44: =IF(AND(ISNUMBER(E44),ISNUMBER(F44)),IF(F44>0,E44/F44,""),"") -> 9 | K44: =IF(AND(ISNUMBER(G44),ISNUMBER(H44)),IF(H44>0,G44/H44,""),"") -> 6 | L44: =IF(AND(ISNUMBER(J44),ISNUMBER(K44)),IF(J44>0,K44/J44,""),"") -> 0.66666667
A45: 46307 | B45: Fachada e reboco externo | D45: =IF(B45="","",IFERROR(VLOOKUP(B45,Frentes!$A$5:$B$64,2,0),"")) -> m² | E45: 620 | F45: 15 | I45: Depende do balancim (restrição de equipamento, prazo 21/10). Sem ele, manter 12 pessoas. | J45: =IF(AND(ISNUMBER(E45),ISNUMBER(F45)),IF(F45>0,E45/F45,""),"") -> 41.333333 | K45: =IF(AND(ISNUMBER(G45),ISNUMBER(H45)),IF(H45>0,G45/H45,""),"") | L45: =IF(AND(ISNUMBER(J45),ISNUMBER(K45)),IF(J45>0,K45/J45,""),"")
A46: 46307 | B46: Regularização de escadas | D46: =IF(B46="","",IFERROR(VLOOKUP(B46,Frentes!$A$5:$B$64,2,0),"")) -> lance | E46: 4 | F46: 6 | I46: Frente estável, com a mesma equipe nas três primeiras semanas. | J46: =IF(AND(ISNUMBER(E46),ISNUMBER(F46)),IF(F46>0,E46/F46,""),"") -> 0.66666667 | K46: =IF(AND(ISNUMBER(G46),ISNUMBER(H46)),IF(H46>0,G46/H46,""),"") | L46: =IF(AND(ISNUMBER(J46),ISNUMBER(K46)),IF(J46>0,K46/J46,""),"")
A47: 46307 | B47: Instalações elétricas | D47: =IF(B47="","",IFERROR(VLOOKUP(B47,Frentes!$A$5:$B$64,2,0),"")) -> pontos | E47: 170 | F47: 12 | I47: Queda a partir da S3: o trabalho nos shafts termina. | J47: =IF(AND(ISNUMBER(E47),ISNUMBER(F47)),IF(F47>0,E47/F47,""),"") -> 14.166667 | K47: =IF(AND(ISNUMBER(G47),ISNUMBER(H47)),IF(H47>0,G47/H47,""),"") | L47: =IF(AND(ISNUMBER(J47),ISNUMBER(K47)),IF(J47>0,K47/J47,""),"")
A48: 46307 | B48: Alvenaria e shafts | D48: =IF(B48="","",IFERROR(VLOOKUP(B48,Frentes!$A$5:$B$64,2,0),"")) -> m² | E48: 400 | F48: 16 | I48: 18 pessoas na S3 só se o aditivo da equipe for aprovado até 14/10. | J48: =IF(AND(ISNUMBER(E48),ISNUMBER(F48)),IF(F48>0,E48/F48,""),"") -> 25 | K48: =IF(AND(ISNUMBER(G48),ISNUMBER(H48)),IF(H48>0,G48/H48,""),"") | L48: =IF(AND(ISNUMBER(J48),ISNUMBER(K48)),IF(J48>0,K48/J48,""),"")
A49: 46307 | B49: Forro e tratamento de teto | D49: =IF(B49="","",IFERROR(VLOOKUP(B49,Frentes!$A$5:$B$64,2,0),"")) -> m² | E49: 260 | F49: 8 | I49: Uma equipe fixa no estacionamento do SS1. | J49: =IF(AND(ISNUMBER(E49),ISNUMBER(F49)),IF(F49>0,E49/F49,""),"") -> 32.5 | K49: =IF(AND(ISNUMBER(G49),ISNUMBER(H49)),IF(H49>0,G49/H49,""),"") | L49: =IF(AND(ISNUMBER(J49),ISNUMBER(K49)),IF(J49>0,K49/J49,""),"")
A50: 46307 | B50: Fechamento da cremalheira | D50: =IF(B50="","",IFERROR(VLOOKUP(B50,Frentes!$A$5:$B$64,2,0),"")) -> pav. | E50: 8 | F50: 10 | I50: Meta de 8 pavimentos por semana a partir da S2, com a mesma equipe. | J50: =IF(AND(ISNUMBER(E50),ISNUMBER(F50)),IF(F50>0,E50/F50,""),"") -> 0.8 | K50: =IF(AND(ISNUMBER(G50),ISNUMBER(H50)),IF(H50>0,G50/H50,""),"") | L50: =IF(AND(ISNUMBER(J50),ISNUMBER(K50)),IF(J50>0,K50/J50,""),"")
A51: 46307 | B51: Impermeabilização | D51: =IF(B51="","",IFERROR(VLOOKUP(B51,Frentes!$A$5:$B$64,2,0),"")) -> m² | E51: 320 | F51: 10 | I51: Mais 2 pessoas a partir da S2, quando entram as etapas da Torre 2. | J51: =IF(AND(ISNUMBER(E51),ISNUMBER(F51)),IF(F51>0,E51/F51,""),"") -> 32 | K51: =IF(AND(ISNUMBER(G51),ISNUMBER(H51)),IF(H51>0,G51/H51,""),"") | L51: =IF(AND(ISNUMBER(J51),ISNUMBER(K51)),IF(J51>0,K51/J51,""),"")
A52: 46307 | B52: Contrapiso e pavimentação | D52: =IF(B52="","",IFERROR(VLOOKUP(B52,Frentes!$A$5:$B$64,2,0),"")) -> m² | E52: 540 | F52: 10 | I52: Equipe reduz na S3, quando restam só os halls. | J52: =IF(AND(ISNUMBER(E52),ISNUMBER(F52)),IF(F52>0,E52/F52,""),"") -> 54 | K52: =IF(AND(ISNUMBER(G52),ISNUMBER(H52)),IF(H52>0,G52/H52,""),"") | L52: =IF(AND(ISNUMBER(J52),ISNUMBER(K52)),IF(J52>0,K52/J52,""),"")
A53: 46307 | B53: Reboco interno | D53: =IF(B53="","",IFERROR(VLOOKUP(B53,Frentes!$A$5:$B$64,2,0),"")) -> m² | E53: 260 | F53: 10 | I53: Reforço de 4 pessoas na S3, condicionado à argamassa (restrição de material). | J53: =IF(AND(ISNUMBER(E53),ISNUMBER(F53)),IF(F53>0,E53/F53,""),"") -> 26 | K53: =IF(AND(ISNUMBER(G53),ISNUMBER(H53)),IF(H53>0,G53/H53,""),"") | L53: =IF(AND(ISNUMBER(J53),ISNUMBER(K53)),IF(J53>0,K53/J53,""),"")
A54: 46307 | B54: Instalações hidráulicas | D54: =IF(B54="","",IFERROR(VLOOKUP(B54,Frentes!$A$5:$B$64,2,0),"")) -> pontos | E54: 100 | F54: 6 | I54: Frente encerra na S2. | J54: =IF(AND(ISNUMBER(E54),ISNUMBER(F54)),IF(F54>0,E54/F54,""),"") -> 16.666667 | K54: =IF(AND(ISNUMBER(G54),ISNUMBER(H54)),IF(H54>0,G54/H54,""),"") | L54: =IF(AND(ISNUMBER(J54),ISNUMBER(K54)),IF(J54>0,K54/J54,""),"")
A55: 46314 | B55: Fachada e reboco externo | D55: =IF(B55="","",IFERROR(VLOOKUP(B55,Frentes!$A$5:$B$64,2,0),"")) -> m² | E55: 620 | F55: 15 | J55: =IF(AND(ISNUMBER(E55),ISNUMBER(F55)),IF(F55>0,E55/F55,""),"") -> 41.333333 | K55: =IF(AND(ISNUMBER(G55),ISNUMBER(H55)),IF(H55>0,G55/H55,""),"") | L55: =IF(AND(ISNUMBER(J55),ISNUMBER(K55)),IF(J55>0,K55/J55,""),"")
A56: 46314 | B56: Regularização de escadas | D56: =IF(B56="","",IFERROR(VLOOKUP(B56,Frentes!$A$5:$B$64,2,0),"")) -> lance | E56: 4 | F56: 6 | J56: =IF(AND(ISNUMBER(E56),ISNUMBER(F56)),IF(F56>0,E56/F56,""),"") -> 0.66666667 | K56: =IF(AND(ISNUMBER(G56),ISNUMBER(H56)),IF(H56>0,G56/H56,""),"") | L56: =IF(AND(ISNUMBER(J56),ISNUMBER(K56)),IF(J56>0,K56/J56,""),"")
A57: 46314 | B57: Instalações elétricas | D57: =IF(B57="","",IFERROR(VLOOKUP(B57,Frentes!$A$5:$B$64,2,0),"")) -> pontos | E57: 110 | F57: 8 | J57: =IF(AND(ISNUMBER(E57),ISNUMBER(F57)),IF(F57>0,E57/F57,""),"") -> 13.75 | K57: =IF(AND(ISNUMBER(G57),ISNUMBER(H57)),IF(H57>0,G57/H57,""),"") | L57: =IF(AND(ISNUMBER(J57),ISNUMBER(K57)),IF(J57>0,K57/J57,""),"")
A58: 46314 | B58: Alvenaria e shafts | D58: =IF(B58="","",IFERROR(VLOOKUP(B58,Frentes!$A$5:$B$64,2,0),"")) -> m² | E58: 480 | F58: 18 | J58: =IF(AND(ISNUMBER(E58),ISNUMBER(F58)),IF(F58>0,E58/F58,""),"") -> 26.666667 | K58: =IF(AND(ISNUMBER(G58),ISNUMBER(H58)),IF(H58>0,G58/H58,""),"") | L58: =IF(AND(ISNUMBER(J58),ISNUMBER(K58)),IF(J58>0,K58/J58,""),"")
A59: 46314 | B59: Forro e tratamento de teto | D59: =IF(B59="","",IFERROR(VLOOKUP(B59,Frentes!$A$5:$B$64,2,0),"")) -> m² | E59: 260 | F59: 8 | J59: =IF(AND(ISNUMBER(E59),ISNUMBER(F59)),IF(F59>0,E59/F59,""),"") -> 32.5 | K59: =IF(AND(ISNUMBER(G59),ISNUMBER(H59)),IF(H59>0,G59/H59,""),"") | L59: =IF(AND(ISNUMBER(J59),ISNUMBER(K59)),IF(J59>0,K59/J59,""),"")
A60: 46314 | B60: Fechamento da cremalheira | D60: =IF(B60="","",IFERROR(VLOOKUP(B60,Frentes!$A$5:$B$64,2,0),"")) -> pav. | E60: 8 | F60: 10 | J60: =IF(AND(ISNUMBER(E60),ISNUMBER(F60)),IF(F60>0,E60/F60,""),"") -> 0.8 | K60: =IF(AND(ISNUMBER(G60),ISNUMBER(H60)),IF(H60>0,G60/H60,""),"") | L60: =IF(AND(ISNUMBER(J60),ISNUMBER(K60)),IF(J60>0,K60/J60,""),"")
A61: 46314 | B61: Impermeabilização | D61: =IF(B61="","",IFERROR(VLOOKUP(B61,Frentes!$A$5:$B$64,2,0),"")) -> m² | E61: 320 | F61: 10 | J61: =IF(AND(ISNUMBER(E61),ISNUMBER(F61)),IF(F61>0,E61/F61,""),"") -> 32 | K61: =IF(AND(ISNUMBER(G61),ISNUMBER(H61)),IF(H61>0,G61/H61,""),"") | L61: =IF(AND(ISNUMBER(J61),ISNUMBER(K61)),IF(J61>0,K61/J61,""),"")
A62: 46314 | B62: Contrapiso e pavimentação | D62: =IF(B62="","",IFERROR(VLOOKUP(B62,Frentes!$A$5:$B$64,2,0),"")) -> m² | E62: 400 | F62: 8 | J62: =IF(AND(ISNUMBER(E62),ISNUMBER(F62)),IF(F62>0,E62/F62,""),"") -> 50 | K62: =IF(AND(ISNUMBER(G62),ISNUMBER(H62)),IF(H62>0,G62/H62,""),"") | L62: =IF(AND(ISNUMBER(J62),ISNUMBER(K62)),IF(J62>0,K62/J62,""),"")
A63: 46314 | B63: Reboco interno | D63: =IF(B63="","",IFERROR(VLOOKUP(B63,Frentes!$A$5:$B$64,2,0),"")) -> m² | E63: 400 | F63: 14 | J63: =IF(AND(ISNUMBER(E63),ISNUMBER(F63)),IF(F63>0,E63/F63,""),"") -> 28.571429 | K63: =IF(AND(ISNUMBER(G63),ISNUMBER(H63)),IF(H63>0,G63/H63,""),"") | L63: =IF(AND(ISNUMBER(J63),ISNUMBER(K63)),IF(J63>0,K63/J63,""),"")
A64: 46321 | B64: Fachada e reboco externo | D64: =IF(B64="","",IFERROR(VLOOKUP(B64,Frentes!$A$5:$B$64,2,0),"")) -> m² | E64: 600 | F64: 15 | J64: =IF(AND(ISNUMBER(E64),ISNUMBER(F64)),IF(F64>0,E64/F64,""),"") -> 40 | K64: =IF(AND(ISNUMBER(G64),ISNUMBER(H64)),IF(H64>0,G64/H64,""),"") | L64: =IF(AND(ISNUMBER(J64),ISNUMBER(K64)),IF(J64>0,K64/J64,""),"")
A65: 46321 | B65: Regularização de escadas | D65: =IF(B65="","",IFERROR(VLOOKUP(B65,Frentes!$A$5:$B$64,2,0),"")) -> lance | E65: 2 | F65: 4 | J65: =IF(AND(ISNUMBER(E65),ISNUMBER(F65)),IF(F65>0,E65/F65,""),"") -> 0.5 | K65: =IF(AND(ISNUMBER(G65),ISNUMBER(H65)),IF(H65>0,G65/H65,""),"") | L65: =IF(AND(ISNUMBER(J65),ISNUMBER(K65)),IF(J65>0,K65/J65,""),"")
A66: 46321 | B66: Instalações elétricas | D66: =IF(B66="","",IFERROR(VLOOKUP(B66,Frentes!$A$5:$B$64,2,0),"")) -> pontos | E66: 90 | F66: 8 | J66: =IF(AND(ISNUMBER(E66),ISNUMBER(F66)),IF(F66>0,E66/F66,""),"") -> 11.25 | K66: =IF(AND(ISNUMBER(G66),ISNUMBER(H66)),IF(H66>0,G66/H66,""),"") | L66: =IF(AND(ISNUMBER(J66),ISNUMBER(K66)),IF(J66>0,K66/J66,""),"")
... A72: 46321 | B72: Reboco interno | D72: =IF(B72="","",IFERROR(VLOOKUP(B72,Frentes!$A$5:$B$64,2,0),"")) -> m² | E72: 420 | F72: 14 | J72: =IF(AND(ISNUMBER(E72),ISNUMBER(F72)),IF(F72>0,E72/F72,""),"") -> 30 | K72: =IF(AND(ISNUMBER(G72),ISNUMBER(H72)),IF(H72>0,G72/H72,""),"") | L72: =IF(AND(ISNUMBER(J72),ISNUMBER(K72)),IF(J72>0,K72/J72,""),"")
D73: =IF(B73="","",IFERROR(VLOOKUP(B73,Frentes!$A$5:$B$64,2,0),"")) | J73: =IF(AND(ISNUMBER(E73),ISNUMBER(F73)),IF(F73>0,E73/F73,""),"") | K73: =IF(AND(ISNUMBER(G73),ISNUMBER(H73)),IF(H73>0,G73/H73,""),"") | L73: =IF(AND(ISNUMBER(J73),ISNUMBER(K73)),IF(J73>0,K73/J73,""),"")
...

Sheet Planos de ação
A1: Planos de ação
A2: Registro de ações para tratamento das restrições e desvios.
A4: AÇÃO | B4: FRENTE | C4: RESPONSÁVEL | D4: PRAZO | E4: STATUS | F4: OBSERVAÇÃO | G4: SITUAÇÃO
A5: Cotar e fechar a locação dos balancins para a fachada | B5: Fachada e reboco externo | C5: Suprimentos | D5: 46316 | E5: Em andamento | F5: Três cotações em análise | G5: =IF(A5="","",IF(E5="Concluída","Concluída",IF(D5<DataRef,"Atrasada","No prazo"))) -> No prazo
A6: Aprovar o aditivo da equipe de alvenaria | B6: Alvenaria e shafts | C6: Contratos | D6: 46309 | E6: Em andamento | F6: Libera as 18 pessoas previstas para a S3 | G6: =IF(A6="","",IF(E6="Concluída","Concluída",IF(D6<DataRef,"Atrasada","No prazo"))) -> No prazo
A7: Emitir o pedido de compra da argamassa de reboco interno | B7: Reboco interno | C7: Compras | D7: 46311 | E7: Em andamento | G7: =IF(A7="","",IF(E7="Concluída","Concluída",IF(D7<DataRef,"Atrasada","No prazo"))) -> No prazo
A8: Fechar o projeto de prumadas com o projetista | B8: Instalações hidráulicas | C8: Projetos | D8: 46304 | E8: Em andamento | F8: Prazo vence amanhã | G8: =IF(A8="","",IF(E8="Concluída","Concluída",IF(D8<DataRef,"Atrasada","No prazo"))) -> No prazo
A9: Antecipar o treinamento de trabalho em altura da equipe de fachada | B9: Fachada e reboco externo | C9: SESMT | D9: 46295 | E9: Concluída | F9: Equipe de 12 pessoas treinada | G9: =IF(A9="","",IF(E9="Concluída","Concluída",IF(D9<DataRef,"Atrasada","No prazo"))) -> Concluída
A10: Rever a sequência de liberação dos pavimentos da cremalheira | B10: Fechamento da cremalheira | C10: Eng. de obra | D10: 46302 | E10: Em andamento | F10: Aguardando reunião com a empreiteira | G10: =IF(A10="","",IF(E10="Concluída","Concluída",IF(D10<DataRef,"Atrasada","No prazo"))) -> Atrasada
A11: Contratar 2 pessoas para a impermeabilização a partir da S2 | B11: Impermeabilização | C11: Contratos | D11: 46307 | E11: Em andamento | G11: =IF(A11="","",IF(E11="Concluída","Concluída",IF(D11<DataRef,"Atrasada","No prazo"))) -> No prazo
A12: Compatibilizar a plataforma elevatória com a frente elétrica | B12: Instalações elétricas | C12: Suprimentos | D12: 46308 | E12: Em andamento | G12: =IF(A12="","",IF(E12="Concluída","Concluída",IF(D12<DataRef,"Atrasada","No prazo"))) -> No prazo
A13: Atualizar o histograma de equipe da alvenaria | B13: Alvenaria e shafts | C13: Planejamento | D13: 46300 | E13: Concluída | F13: Histograma ajustado para 18 pessoas na S3 | G13: =IF(A13="","",IF(E13="Concluída","Concluída",IF(D13<DataRef,"Atrasada","No prazo"))) -> Concluída
A14: Liberar a cobertura para a impermeabilização | B14: Impermeabilização | C14: Eng. de obra | D14: 46310 | E14: Em andamento | F14: Depende da conclusão da estrutura | G14: =IF(A14="","",IF(E14="Concluída","Concluída",IF(D14<DataRef,"Atrasada","No prazo"))) -> No prazo
G15: =IF(A15="","",IF(E15="Concluída","Concluída",IF(D15<DataRef,"Atrasada","No prazo")))
G16: =IF(A16="","",IF(E16="Concluída","Concluída",IF(D16<DataRef,"Atrasada","No prazo")))
G17: =IF(A17="","",IF(E17="Concluída","Concluída",IF(D17<DataRef,"Atrasada","No prazo")))
G18: =IF(A18="","",IF(E18="Concluída","Concluída",IF(D18<DataRef,"Atrasada","No prazo")))
G19: =IF(A19="","",IF(E19="Concluída","Concluída",IF(D19<DataRef,"Atrasada","No prazo")))
G20: =IF(A20="","",IF(E20="Concluída","Concluída",IF(D20<DataRef,"Atrasada","No prazo")))
G21: =IF(A21="","",IF(E21="Concluída","Concluída",IF(D21<DataRef,"Atrasada","No prazo")))
G22: =IF(A22="","",IF(E22="Concluída","Concluída",IF(D22<DataRef,"Atrasada","No prazo")))
G23: =IF(A23="","",IF(E23="Concluída","Concluída",IF(D23<DataRef,"Atrasada","No prazo")))
G24: =IF(A24="","",IF(E24="Concluída","Concluída",IF(D24<DataRef,"Atrasada","No prazo")))
G25: =IF(A25="","",IF(E25="Concluída","Concluída",IF(D25<DataRef,"Atrasada","No prazo")))
G26: =IF(A26="","",IF(E26="Concluída","Concluída",IF(D26<DataRef,"Atrasada","No prazo")))
... G204: =IF(A204="","",IF(E204="Concluída","Concluída",IF(D204<DataRef,"Atrasada","No prazo")))

Sheet Cronograma
A1: Resumo do cronograma
A2: Parâmetros e séries mensais do cronograma.
A4: DATA DO CRONOGRAMA | B4: 46303
A5: TÉRMINO DA OBRA NA LINHA DE BASE | B5: 47105
A6: TÉRMINO DA OBRA NO REPROGRAMADO | B6: 47105
A7: ATIVIDADES PREVISTAS ATÉ HOJE (BASE) | B7: 1262
A8: ATIVIDADES ATRASADAS CONTRA A BASE | B8: 171
A9: ATIVIDADES PREVISTAS ATÉ HOJE (REPROG.) | B9: 1231
A10: ATIVIDADES ATRASADAS CONTRA O REPROG. | B10: 14
A13: MÊS | B13: LINHA DE BASE (%) | C13: REPROGRAMADO (%) | D13: REAL (%)
A14: 44501 | B14: 0.0012799618 | C14: 0.0012578289 | D14: 0.0012578289
A15: 44531 | B15: 0.004091554 | C15: 0.0039915754 | D15: 0.0039915754
A16: 44562 | B16: 0.0056476865 | C16: 0.0056248108 | D16: 0.0056248108
A17: 44593 | B17: 0.0085938642 | C17: 0.0084442331 | D17: 0.0084442331
A18: 44621 | B18: 0.011588961 | C18: 0.011554593 | D18: 0.011554593
A19: 44652 | B19: 0.013539107 | C19: 0.013531032 | D19: 0.013531032
A20: 44682 | B20: 0.017168985 | C20: 0.017098461 | D20: 0.017098461
A21: 44713 | B21: 0.021538648 | C21: 0.021482048 | D21: 0.021482048
A22: 44743 | B22: 0.025859619 | C22: 0.025722325 | D22: 0.025722325
A23: 44774 | B23: 0.029393552 | C23: 0.029320499 | D23: 0.029320499
A24: 44805 | B24: 0.0327827 | C24: 0.032737355 | D24: 0.032737355
A25: 44835 | B25: 0.036147602 | C25: 0.036138991 | D25: 0.036138991
... A73: 46296 | B73: 0.59639442 | C73: 0.59577792 | D73: 0.58596204
A74: 46327 | B74: 0.60941361 | C74: 0.61680655
A75: 46357 | B75: 0.61809008 | C75: 0.63801103
A76: 46388 | B76: 0.62785182 | C76: 0.65699522
A77: 46419 | B77: 0.64434475 | C77: 0.6777468
A78: 46447 | B78: 0.66158601 | C78: 0.70244344
A79: 46478 | B79: 0.67861157 | C79: 0.71621806
A80: 46508 | B80: 0.69170675 | C80: 0.72513384
A81: 46539 | B81: 0.70610143 | C81: 0.73504251
A82: 46569 | B82: 0.7239751 | C82: 0.75409708
A83: 46600 | B83: 0.74167203 | C83: 0.77317794
A84: 46631 | B84: 0.75964255 | C84: 0.78848068
A85: 46661 | B85: 0.77970829 | C85: 0.80538416
... A99: 47088 | B99: 1 | C99: 1

Sheet Listas
A1: Listas e data de referência
A2: Parâmetros e listas de apoio da base. | E2: Data de referência | F2: 46303
A4: TIPO DE RESTRIÇÃO | B4: IMPACTO | C4: STATUS DO PLANO
A5: Material | B5: Alto | C5: Em andamento
A6: Mão de obra | B6: Médio | C6: Concluída
A7: Equipamentos | B7: Baixo
A8: Definição/Projeto
A9: Segurança
A10: Predecessora
