Workbook

Sheet Resumo Gerencial
B3: CHAMADA DE APORTE SEMANAL
B4: Modelo – Resumo Gerencial
B6: GERENCIAMENTO DE OBRAS
B7: Empreendimento: | C7: [NOME DO EMPREENDIMENTO]
B8: CNPJ: | C8: 00.000.000/0001-00
B9: Razão Social: | C9: [RAZÃO SOCIAL DA SPE]
B10: Gestor Vertical: | C10: [NOME DO GESTOR VERTICAL]
B11: Gestor do Contrato: | C11: [NOME DO GESTOR DO CONTRATO]
B13: DADOS DO EMPREENDIMENTO
B14: Empreendimento: | C14: [NOME DO EMPREENDIMENTO]
B15: CNPJ: | C15: 00.000.000/0001-00
B16: Razão Social: | C16: [RAZÃO SOCIAL DA SPE]
B17: Gestor Vertical: | C17: [NOME DO GESTOR VERTICAL]
B18: Gestor do Contrato: | C18: [NOME DO GESTOR DO CONTRATO]
B20: PERÍODO E DATA DO APORTE
B21: Período de Referência (de): | C21: 46238 | D21: até: | E21: 46244
B22: Data do Aporte (descida de recursos):
B24: DADOS BANCÁRIOS PARA DESCIDA DE RECURSOS
B25: Banco: | C25: [BANCO] | D25: Agência: | E25: [AGÊNCIA]
B26: Conta Corrente: | C26: [CONTA CORRENTE] | D26: CNPJ da Conta: | E26: [CNPJ]
B28: RESUMO GERENCIAL DO APORTE
B29: Saldo Bancário | C29: Data: | D29: xx/xx/26
B30: (-) Contas a Pagar – Sistema (já lançadas/pagas no ERP) | E30: =SUMIFS(Tabela1[A_PAGAR], Tabela1[DATA_DE_PAGAMENTO], ">="&C21, Tabela1[DATA_DE_PAGAMENTO], "<="&E21) -> 0
B31: (-) Contas a Lançar – Gerencial (previstas, ainda não lançadas) | E31: =SUM(Tabela3[VALOR PREVISTO]) -> 0
B32: TOTAL DE SAÍDAS DO PERÍODO | E32: =E30+E31 -> 0
B33: (-) Fundo de Reserva
B35: VALOR DO APORTE SOLICITADO
B36: Valor do Aporte Necessário | E36: =E32+E33-E29 -> 0
B38: RATEIO DO APORTE POR INVESTIDOR (opcional)
B39: Investidor / Quotista | D39: % Participação | E39: Valor do Aporte
B40: [Investidor 1] | D40: 1 | E40: =$E$36*D40 -> 0
B41: TOTAL | D41: =SUM(D40:D40) -> 0 | E41: =SUM(E40:E40) -> 0
B43: EXECUÇÃO ORÇAMENTÁRIA (EAP)
B44: Orçamento Alvo Total | E44: ='Controle EAP'!I6 -> 0
B45: Incorrido Acumulado Total (Pago) | E45: ='Controle EAP'!J6 -> 0
B46: Saldo Orçamentário Disponível | E46: =E44-E45 -> 0
B47: % Executado do Orçamento | E47: =E45/E44 -> 0
B51: Legenda:
B52: Amarelo = célula de preenchimento manual
B53: Branco (fórmula) = calculado automaticamente

Sheet CONFIG
B3: {=_xlfn._xlws.FILTER('Controle EAP'!G7:G279,'Controle EAP'!F7:F279=4,"")} -> 01.001.001.001 | C3: {=_xlfn._xlws.FILTER('Controle EAP'!D7:D279,'Controle EAP'!F7:F279=4,"")} -> SERVIÇO DE ELABORAÇÃO DE MANUAL DO PROPRIETÁRIO | D3: =_xlfn.CONCAT(B3,"-",LEFT(C3,100)) -> 01.001.001.001-SERVIÇO DE ELABORAÇÃO DE MANUAL DO PROPRIETÁRIO
B4: 01.001.002.001 | C4: BARRACÕES DE OBRA | D4: =_xlfn.CONCAT(B4,"-",LEFT(C4,100)) -> 01.001.002.001-BARRACÕES DE OBRA
B5: 01.001.002.002 | C5: INSTALAÇÕES PROVISORIAS DE AGUA E ESGOTO | D5: =_xlfn.CONCAT(B5,"-",LEFT(C5,100)) -> 01.001.002.002-INSTALAÇÕES PROVISORIAS DE AGUA E ESGOTO
B6: 01.001.002.003 | C6: INSTALAÇÕES PROVISORIAS DE ENERGIA | D6: =_xlfn.CONCAT(B6,"-",LEFT(C6,100)) -> 01.001.002.003-INSTALAÇÕES PROVISORIAS DE ENERGIA
B7: 01.001.002.004 | C7: SERVIÇO PRESTADO - EQUIPE DE APOIO DE CANTEIRO DE OBRA | D7: =_xlfn.CONCAT(B7,"-",LEFT(C7,100)) -> 01.001.002.004-SERVIÇO PRESTADO - EQUIPE DE APOIO DE CANTEIRO DE OBRA
B8: 01.001.002.005 | C8: SERVIÇO DE EXECUÇÃO DE INSTALAÇÃO DO SISTEMA DE ALARME/SEGURANÇA | D8: =_xlfn.CONCAT(B8,"-",LEFT(C8,100)) -> 01.001.002.005-SERVIÇO DE EXECUÇÃO DE INSTALAÇÃO DO SISTEMA DE ALARME/SEGURANÇA
B9: 01.001.002.006 | C9: SERVIÇO DE MANUTENÇÃO DE ALARME DE SEGURANÇA | D9: =_xlfn.CONCAT(B9,"-",LEFT(C9,100)) -> 01.001.002.006-SERVIÇO DE MANUTENÇÃO DE ALARME DE SEGURANÇA
B10: 01.001.002.007 | C10: INSTALAÇÕES DE CANTEIRO | D10: =_xlfn.CONCAT(B10,"-",LEFT(C10,100)) -> 01.001.002.007-INSTALAÇÕES DE CANTEIRO
B11: 01.001.002.008 | C11: OUTRAS MANUTENÇÕES DE CANTEIRO E SUPORTES TÉCNICOS | D11: =_xlfn.CONCAT(B11,"-",LEFT(C11,100)) -> 01.001.002.008-OUTRAS MANUTENÇÕES DE CANTEIRO E SUPORTES TÉCNICOS
B12: 01.001.002.009 | C12: SERVIÇO DE INSTALAÇÃO DE TAPUME | D12: =_xlfn.CONCAT(B12,"-",LEFT(C12,100)) -> 01.001.002.009-SERVIÇO DE INSTALAÇÃO DE TAPUME
B13: 01.001.002.010 | C13: RETIRADA DE TAPUME | D13: =_xlfn.CONCAT(B13,"-",LEFT(C13,100)) -> 01.001.002.010-RETIRADA DE TAPUME
B14: 01.001.002.011 | C14: SERVIÇO DE SERRALHERIA EM GERAL | D14: =_xlfn.CONCAT(B14,"-",LEFT(C14,100)) -> 01.001.002.011-SERVIÇO DE SERRALHERIA EM GERAL
B15: 01.001.002.012 | C15: TAPUME | D15: =_xlfn.CONCAT(B15,"-",LEFT(C15,100)) -> 01.001.002.012-TAPUME
... B245: 01.002.016.024 | C245: CONCRETO USINADO 25MPA SLUMP12+-2 | D245: =_xlfn.CONCAT(B245,"-",LEFT(C245,100)) -> 01.002.016.024-CONCRETO USINADO 25MPA SLUMP12+-2
B246: 01.002.016.025 | C246: ARGAMASSA COLORIDA PARA SELAR JUNTAS ATÉ 4 MM COR BRANCA COLORSTUK 0-4 BLANCO (HOMOLOGADO)
B247: 01.002.016.026 | C247: ARGAMASSA COLORIDA PARA SELAR JUNTAS ATÉ 4 MM COR MANHATTAN - COLORSTUK 0-4 MANHATTAN N 5 KG (HOMOLOGADO)
B248: 01.002.016.027 | C248: ARGAMASSA COLORIDA PARA SELAR JUNTAS ATÉ 4 MM COR MOKA - COLORSTUK 0-4 MOKA N 5 KG (HOMOLOGADO)
B249: 01.002.016.028 | C249: CRUZETAS AUTONIVELANTES 2MM (1 BOLSA CONTEM 500 CRUZETAS) (HOMOLOGADO)
B250: 01.002.016.029 | C250: CUNHA PARA NIVELAR OS REVESTIMENTOS CERAMICOS (1 BOLSA CONTEM 500 CUNHAS) (HOMOLOGADO)
B251: 01.002.016.030 | C251: FERRAMENTA MANUAL PARA AJUSTE ENTRE CUNHA E CRUZETA PARA NIVELAMENTO DE REVESTIMENTOS CERAMICOS (HOMOLOGADO)

Sheet Controle EAP
B2: CONTROLE EAP - ORÇADO x INCORRIDO ([NOME DA OBRA])
B3: Base: orçamento-alvo enviado (arquivo de orçamento da obra). O incorrido é somado automaticamente a partir da aba Detalhado pelo Código EAP (De-Para).
B5: ITEM_PL | C5: COD_SERVICO | D5: DESCRICAO | E5: TIPO_HIERARQUICO | F5: NIVEL | G5: ITEM | H5: CHAVE | I5: VALOR ORÇADO | J5: VALOR INCORRIDO | K5: SALDO DE ORÇAMENTO
D6: CUSTO OBRA | H6: =IF(F6=4,B6&" - "&C6,"") | I6: =SUMIFS(I:I,$F:$F,1) -> 0 | J6: =SUMIFS(J:J,$F:$F,1) -> 0 | K6: =I6-J6 -> 0
B7: 1 | C7: -1 | D7: OBRA | E7: FASE | F7: 1 | G7: 01 | H7: =IF(F7=4,B7&" - "&C7,"") | I7: =SUMIFS(I:I,$G:$G,'Controle EAP'!G7&"????") -> 0 | J7: =IF(F7=4,SUMIFS(Tabela1[PAGO],Tabela1[CHAVE],'Controle EAP'!H7),SUMIFS(J:J,$G:$G,'Controle EAP'!G7&"????")) -> 0 | K7: =I7-J7 -> 0
B8: 01.01 | C8: -1 | D8: CUSTO INDIRETO DA OBRA | E8: FASE | F8: 2 | G8: 01.001 | H8: =IF(F8=4,B8&" - "&C8,"") | I8: =SUMIFS(I:I,$G:$G,'Controle EAP'!G8&"????") -> 0 | J8: =IF(F8=4,SUMIFS(Tabela1[PAGO],Tabela1[CHAVE],'Controle EAP'!H8),SUMIFS(J:J,$G:$G,'Controle EAP'!G8&"????")) -> 0 | K8: =I8-J8 -> 0
B9: 01.01.01 | C9: -1 | D9: SERVICOS PRELIMINARES E GERAIS | E9: FASE | F9: 3 | G9: 01.001.001 | H9: =IF(F9=4,B9&" - "&C9,"") | I9: =SUMIFS(I:I,$G:$G,'Controle EAP'!G9&"????") -> 0 | J9: =IF(F9=4,SUMIFS(Tabela1[PAGO],Tabela1[CHAVE],'Controle EAP'!H9),SUMIFS(J:J,$G:$G,'Controle EAP'!G9&"????")) -> 0 | K9: =I9-J9 -> 0
B10: 01.01.01.01 | C10: C18612 | D10: SERVIÇO DE ELABORAÇÃO DE MANUAL DO PROPRIETÁRIO | E10: SERVIÇO | F10: 4 | G10: 01.001.001.001 | H10: =IF(F10=4,B10&" - "&C10,"") -> 01.01.01.01 - C18612 | I10: 0 | J10: =IF(F10=4,SUMIFS(Tabela1[PAGO],Tabela1[CHAVE],'Controle EAP'!H10),SUMIFS(J:J,$G:$G,'Controle EAP'!G10&"????")) -> 0 | K10: =I10-J10 -> 0
B11: 01.01.02 | C11: -1 | D11: IMPLANTACAO DA OBRA | E11: FASE | F11: 3 | G11: 01.001.002 | H11: =IF(F11=4,B11&" - "&C11,"") | I11: =SUMIFS(I:I,$G:$G,'Controle EAP'!G11&"????") -> 0 | J11: =IF(F11=4,SUMIFS(Tabela1[PAGO],Tabela1[CHAVE],'Controle EAP'!H11),SUMIFS(J:J,$G:$G,'Controle EAP'!G11&"????")) -> 0 | K11: =I11-J11 -> 0
B12: 01.01.02.01 | C12: C18698 | D12: BARRACÕES DE OBRA | E12: SERVIÇO | F12: 4 | G12: 01.001.002.001 | H12: =IF(F12=4,B12&" - "&C12,"") -> 01.01.02.01 - C18698 | I12: 0 | J12: =IF(F12=4,SUMIFS(Tabela1[PAGO],Tabela1[CHAVE],'Controle EAP'!H12),SUMIFS(J:J,$G:$G,'Controle EAP'!G12&"????")) -> 0 | K12: =I12-J12 -> 0
B13: 01.01.02.02 | C13: C18700 | D13: INSTALAÇÕES PROVISORIAS DE AGUA E ESGOTO | E13: SERVIÇO | F13: 4 | G13: 01.001.002.002 | H13: =IF(F13=4,B13&" - "&C13,"") -> 01.01.02.02 - C18700 | I13: 0 | J13: =IF(F13=4,SUMIFS(Tabela1[PAGO],Tabela1[CHAVE],'Controle EAP'!H13),SUMIFS(J:J,$G:$G,'Controle EAP'!G13&"????")) -> 0 | K13: =I13-J13 -> 0
B14: 01.01.02.03 | C14: C18701 | D14: INSTALAÇÕES PROVISORIAS DE ENERGIA | E14: SERVIÇO | F14: 4 | G14: 01.001.002.003 | H14: =IF(F14=4,B14&" - "&C14,"") -> 01.01.02.03 - C18701 | I14: 0 | J14: =IF(F14=4,SUMIFS(Tabela1[PAGO],Tabela1[CHAVE],'Controle EAP'!H14),SUMIFS(J:J,$G:$G,'Controle EAP'!G14&"????")) -> 0 | K14: =I14-J14 -> 0
B15: 01.01.02.04 | C15: C15897 | D15: SERVIÇO PRESTADO - EQUIPE DE APOIO DE CANTEIRO DE OBRA | E15: SERVIÇO | F15: 4 | G15: 01.001.002.004 | H15: =IF(F15=4,B15&" - "&C15,"") -> 01.01.02.04 - C15897 | I15: 0 | J15: =IF(F15=4,SUMIFS(Tabela1[PAGO],Tabela1[CHAVE],'Controle EAP'!H15),SUMIFS(J:J,$G:$G,'Controle EAP'!G15&"????")) -> 0 | K15: =I15-J15 -> 0
B16: 01.01.02.05 | C16: C19273 | D16: SERVIÇO DE EXECUÇÃO DE INSTALAÇÃO DO SISTEMA DE ALARME/SEGURANÇA | E16: SERVIÇO | F16: 4 | G16: 01.001.002.005 | H16: =IF(F16=4,B16&" - "&C16,"") -> 01.01.02.05 - C19273 | I16: 0 | J16: =IF(F16=4,SUMIFS(Tabela1[PAGO],Tabela1[CHAVE],'Controle EAP'!H16),SUMIFS(J:J,$G:$G,'Controle EAP'!G16&"????")) -> 0 | K16: =I16-J16 -> 0
B17: 01.01.02.06 | C17: C12930 | D17: SERVIÇO DE MANUTENÇÃO DE ALARME DE SEGURANÇA | E17: SERVIÇO | F17: 4 | G17: 01.001.002.006 | H17: =IF(F17=4,B17&" - "&C17,"") -> 01.01.02.06 - C12930 | I17: 0 | J17: =IF(F17=4,SUMIFS(Tabela1[PAGO],Tabela1[CHAVE],'Controle EAP'!H17),SUMIFS(J:J,$G:$G,'Controle EAP'!G17&"????")) -> 0 | K17: =I17-J17 -> 0
B18: 01.01.02.07 | C18: C17211 | D18: INSTALAÇÕES DE CANTEIRO | E18: SERVIÇO | F18: 4 | G18: 01.001.002.007 | H18: =IF(F18=4,B18&" - "&C18,"") -> 01.01.02.07 - C17211 | I18: 0 | J18: =IF(F18=4,SUMIFS(Tabela1[PAGO],Tabela1[CHAVE],'Controle EAP'!H18),SUMIFS(J:J,$G:$G,'Controle EAP'!G18&"????")) -> 0 | K18: =I18-J18 -> 0
B19: 01.01.02.08 | C19: CO330 | D19: OUTRAS MANUTENÇÕES DE CANTEIRO E SUPORTES TÉCNICOS | E19: SERVIÇO | F19: 4 | G19: 01.001.002.008 | H19: =IF(F19=4,B19&" - "&C19,"") -> 01.01.02.08 - CO330 | I19: 0 | J19: =IF(F19=4,SUMIFS(Tabela1[PAGO],Tabela1[CHAVE],'Controle EAP'!H19),SUMIFS(J:J,$G:$G,'Controle EAP'!G19&"????")) -> 0 | K19: =I19-J19 -> 0
B20: 01.01.02.09 | C20: C12643 | D20: SERVIÇO DE INSTALAÇÃO DE TAPUME | E20: SERVIÇO | F20: 4 | G20: 01.001.002.009 | H20: =IF(F20=4,B20&" - "&C20,"") -> 01.01.02.09 - C12643 | I20: 0 | J20: =IF(F20=4,SUMIFS(Tabela1[PAGO],Tabela1[CHAVE],'Controle EAP'!H20),SUMIFS(J:J,$G:$G,'Controle EAP'!G20&"????")) -> 0 | K20: =I20-J20 -> 0
B21: 01.01.02.11 | C21: C19930 | D21: RETIRADA DE TAPUME | E21: SERVIÇO | F21: 4 | G21: 01.001.002.010 | H21: =IF(F21=4,B21&" - "&C21,"") -> 01.01.02.11 - C19930 | I21: 0 | J21: =IF(F21=4,SUMIFS(Tabela1[PAGO],Tabela1[CHAVE],'Controle EAP'!H21),SUMIFS(J:J,$G:$G,'Controle EAP'!G21&"????")) -> 0 | K21: =I21-J21 -> 0
B22: 01.01.02.13 | C22: C15008 | D22: SERVIÇO DE SERRALHERIA EM GERAL | E22: SERVIÇO | F22: 4 | G22: 01.001.002.011 | H22: =IF(F22=4,B22&" - "&C22,"") -> 01.01.02.13 - C15008 | I22: 0 | J22: =IF(F22=4,SUMIFS(Tabela1[PAGO],Tabela1[CHAVE],'Controle EAP'!H22),SUMIFS(J:J,$G:$G,'Controle EAP'!G22&"????")) -> 0 | K22: =I22-J22 -> 0
B23: 01.01.02.14 | C23: C15194 | D23: TAPUME | E23: SERVIÇO | F23: 4 | G23: 01.001.002.012 | H23: =IF(F23=4,B23&" - "&C23,"") -> 01.01.02.14 - C15194 | I23: 0 | J23: =IF(F23=4,SUMIFS(Tabela1[PAGO],Tabela1[CHAVE],'Controle EAP'!H23),SUMIFS(J:J,$G:$G,'Controle EAP'!G23&"????")) -> 0 | K23: =I23-J23 -> 0
... B25: 01.01.02.17 | C25: C18702 | D25: PLACAS DE OBRA | E25: SERVIÇO | F25: 4 | G25: 01.001.002.014 | H25: =IF(F25=4,B25&" - "&C25,"") -> 01.01.02.17 - C18702 | I25: 0 | J25: =IF(F25=4,SUMIFS(Tabela1[PAGO],Tabela1[CHAVE],'Controle EAP'!H25),SUMIFS(J:J,$G:$G,'Controle EAP'!G25&"????")) -> 0 | K25: =I25-J25 -> 0
B26: 01.01.03 | C26: -1 | D26: EQUIPAMENTOS/FERRAMENTAS | E26: FASE | F26: 3 | G26: 01.001.003 | H26: =IF(F26=4,B26&" - "&C26,"") | I26: =SUMIFS(I:I,$G:$G,'Controle EAP'!G26&"????") -> 0 | J26: =IF(F26=4,SUMIFS(Tabela1[PAGO],Tabela1[CHAVE],'Controle EAP'!H26),SUMIFS(J:J,$G:$G,'Controle EAP'!G26&"????")) -> 0 | K26: =I26-J26 -> 0
B27: 01.01.03.01 | C27: C17519 | D27: SERVIÇO DE MANUTENÇÃO DE CONTROLE DE AR CONDICIONADO | E27: SERVIÇO | F27: 4 | G27: 01.001.003.001 | H27: =IF(F27=4,B27&" - "&C27,"") -> 01.01.03.01 - C17519 | I27: 0 | J27: =IF(F27=4,SUMIFS(Tabela1[PAGO],Tabela1[CHAVE],'Controle EAP'!H27),SUMIFS(J:J,$G:$G,'Controle EAP'!G27&"????")) -> 0 | K27: =I27-J27 -> 0
B28: 01.01.03.02 | C28: C14888 | D28: SERVIÇO DE INSTALAÇÃO DE BEBEDOUROS | E28: SERVIÇO | F28: 4 | G28: 01.001.003.002 | H28: =IF(F28=4,B28&" - "&C28,"") -> 01.01.03.02 - C14888 | I28: 0 | J28: =IF(F28=4,SUMIFS(Tabela1[PAGO],Tabela1[CHAVE],'Controle EAP'!H28),SUMIFS(J:J,$G:$G,'Controle EAP'!G28&"????")) -> 0 | K28: =I28-J28 -> 0
B29: 01.01.03.03 | C29: C11595 | D29: LOCAÇÃO DIÁRIA DE BETONEIRA 320LT A 400LT SEM CARREGADO R - ALIMENTAÇÃO: ENERGIA ELÉTRICA | E29: SERVIÇO | F29: 4 | G29: 01.001.003.003 | H29: =IF(F29=4,B29&" - "&C29,"") -> 01.01.03.03 - C11595 | I29: 0 | J29: =IF(F29=4,SUMIFS(Tabela1[PAGO],Tabela1[CHAVE],'Controle EAP'!H29),SUMIFS(J:J,$G:$G,'Controle EAP'!G29&"????")) -> 0 | K29: =I29-J29 -> 0
B30: 01.01.03.04 | C30: C18296 | D30: SERVIÇO DE MANUTENÇÃO CORRETIVA DE FURADEIRA | E30: SERVIÇO | F30: 4 | G30: 01.001.003.004 | H30: =IF(F30=4,B30&" - "&C30,"") -> 01.01.03.04 - C18296 | I30: 0 | J30: =IF(F30=4,SUMIFS(Tabela1[PAGO],Tabela1[CHAVE],'Controle EAP'!H30),SUMIFS(J:J,$G:$G,'Controle EAP'!G30&"????")) -> 0 | K30: =I30-J30 -> 0
B31: 01.01.03.05 | C31: C18363 | D31: SERVIÇO DE LAVANDERIA - CAPAS PARA LAVAR | E31: SERVIÇO | F31: 4 | G31: 01.001.003.005 | H31: =IF(F31=4,B31&" - "&C31,"") -> 01.01.03.05 - C18363 | I31: 0 | J31: =IF(F31=4,SUMIFS(Tabela1[PAGO],Tabela1[CHAVE],'Controle EAP'!H31),SUMIFS(J:J,$G:$G,'Controle EAP'!G31&"????")) -> 0 | K31: =I31-J31 -> 0
B32: 01.01.03.06 | C32: C18411 | D32: CORTE DE VIDRO PARA ESTRUTURA METÁLICA | E32: SERVIÇO | F32: 4 | G32: 01.001.003.006 | H32: =IF(F32=4,B32&" - "&C32,"") -> 01.01.03.06 - C18411 | I32: 0 | J32: =IF(F32=4,SUMIFS(Tabela1[PAGO],Tabela1[CHAVE],'Controle EAP'!H32),SUMIFS(J:J,$G:$G,'Controle EAP'!G32&"????")) -> 0 | K32: =I32-J32 -> 0
B33: 01.01.03.07 | C33: C00767 | D33: LAZER | E33: SERVIÇO | F33: 4 | G33: 01.001.003.007 | H33: =IF(F33=4,B33&" - "&C33,"") -> 01.01.03.07 - C00767 | I33: 0 | J33: =IF(F33=4,SUMIFS(Tabela1[PAGO],Tabela1[CHAVE],'Controle EAP'!H33),SUMIFS(J:J,$G:$G,'Controle EAP'!G33&"????")) -> 0 | K33: =I33-J33 -> 0
B34: 01.01.03.08 | C34: C18114 | D34: SERVIÇO DE MANUTENÇÃO DE PISTOLA FINCA PIN | E34: SERVIÇO | F34: 4 | G34: 01.001.003.008 | H34: =IF(F34=4,B34&" - "&C34,"") -> 01.01.03.08 - C18114 | I34: 0 | J34: =IF(F34=4,SUMIFS(Tabela1[PAGO],Tabela1[CHAVE],'Controle EAP'!H34),SUMIFS(J:J,$G:$G,'Controle EAP'!G34&"????")) -> 0 | K34: =I34-J34 -> 0
B35: 01.01.03.09 | C35: C11639 | D35: LOCAÇÃO DIÁRIA DE POLICORTE - ALIMENTAÇÃO: ENERGIA ELÉTRICA | E35: SERVIÇO | F35: 4 | G35: 01.001.003.009 | H35: =IF(F35=4,B35&" - "&C35,"") -> 01.01.03.09 - C11639 | I35: 0 | J35: =IF(F35=4,SUMIFS(Tabela1[PAGO],Tabela1[CHAVE],'Controle EAP'!H35),SUMIFS(J:J,$G:$G,'Controle EAP'!G35&"????")) -> 0 | K35: =I35-J35 -> 0
B36: 01.01.03.10 | C36: C18389 | D36: LOCAÇÃO DE RADIO COMUNICADOR | E36: SERVIÇO | F36: 4 | G36: 01.001.003.010 | H36: =IF(F36=4,B36&" - "&C36,"") -> 01.01.03.10 - C18389 | I36: 0 | J36: =IF(F36=4,SUMIFS(Tabela1[PAGO],Tabela1[CHAVE],'Controle EAP'!H36),SUMIFS(J:J,$G:$G,'Controle EAP'!G36&"????")) -> 0 | K36: =I36-J36 -> 0
B37: 01.01.03.11 | C37: C12852 | D37: SERVIÇO DE MANUTENÇÃO / CONSERTO - SERRA CIRCULAR | E37: SERVIÇO | F37: 4 | G37: 01.001.003.011 | H37: =IF(F37=4,B37&" - "&C37,"") -> 01.01.03.11 - C12852 | I37: 0 | J37: =IF(F37=4,SUMIFS(Tabela1[PAGO],Tabela1[CHAVE],'Controle EAP'!H37),SUMIFS(J:J,$G:$G,'Controle EAP'!G37&"????")) -> 0 | K37: =I37-J37 -> 0
B38: 01.01.03.12 | C38: C17641 | D38: LOCAÇÃO DE MARTELETE ROMPEDOR 7KG | E38: SERVIÇO | F38: 4 | G38: 01.001.003.012 | H38: =IF(F38=4,B38&" - "&C38,"") -> 01.01.03.12 - C17641 | I38: 0 | J38: =IF(F38=4,SUMIFS(Tabela1[PAGO],Tabela1[CHAVE],'Controle EAP'!H38),SUMIFS(J:J,$G:$G,'Controle EAP'!G38&"????")) -> 0 | K38: =I38-J38 -> 0
... B51: 01.01.03.25 | C51: CO608 | D51: BAIA PARA PRODUTOS RECICLAVEIS | E51: SERVIÇO | F51: 4 | G51: 01.001.003.025 | H51: =IF(F51=4,B51&" - "&C51,"") -> 01.01.03.25 - CO608 | I51: 0 | J51: =IF(F51=4,SUMIFS(Tabela1[PAGO],Tabela1[CHAVE],'Controle EAP'!H51),SUMIFS(J:J,$G:$G,'Controle EAP'!G51&"????")) -> 0 | K51: =I51-J51 -> 0
B52: 01.01.04 | C52: -1 | D52: CUSTOS ADMINISTRATIVOS | E52: FASE | F52: 3 | G52: 01.001.004 | H52: =IF(F52=4,B52&" - "&C52,"") | I52: =SUMIFS(I:I,$G:$G,'Controle EAP'!G52&"????") -> 0 | J52: =IF(F52=4,SUMIFS(Tabela1[PAGO],Tabela1[CHAVE],'Controle EAP'!H52),SUMIFS(J:J,$G:$G,'Controle EAP'!G52&"????")) -> 0 | K52: =I52-J52 -> 0
B53: 01.01.04.01 | C53: CO614 | D53: MESTRE DE OBRAS | E53: SERVIÇO | F53: 4 | G53: 01.001.004.001 | H53: =IF(F53=4,B53&" - "&C53,"") -> 01.01.04.01 - CO614 | I53: 0 | J53: =IF(F53=4,SUMIFS(Tabela1[PAGO],Tabela1[CHAVE],'Controle EAP'!H53),SUMIFS(J:J,$G:$G,'Controle EAP'!G53&"????")) -> 0 | K53: =I53-J53 -> 0
B54: 01.01.04.02 | C54: CO454 | D54: GERENTE DE OBRA | E54: SERVIÇO | F54: 4 | G54: 01.001.004.002 | H54: =IF(F54=4,B54&" - "&C54,"") -> 01.01.04.02 - CO454 | I54: 0 | J54: =IF(F54=4,SUMIFS(Tabela1[PAGO],Tabela1[CHAVE],'Controle EAP'!H54),SUMIFS(J:J,$G:$G,'Controle EAP'!G54&"????")) -> 0 | K54: =I54-J54 -> 0
B55: 01.01.04.03 | C55: CO616 | D55: ALMOXARIFE / ADMINISTRATIVO | E55: SERVIÇO | F55: 4 | G55: 01.001.004.003 | H55: =IF(F55=4,B55&" - "&C55,"") -> 01.01.04.03 - CO616 | I55: 0 | J55: =IF(F55=4,SUMIFS(Tabela1[PAGO],Tabela1[CHAVE],'Controle EAP'!H55),SUMIFS(J:J,$G:$G,'Controle EAP'!G55&"????")) -> 0 | K55: =I55-J55 -> 0
...

Sheet Detalhado
B3: PROCESSOS DE PAGAMENTO LANÇADOS NO UAU | P3: CONTRATOS LANÇADOS NO UAU | AB3: CONTAS A LANÇAR – GERENCIAL (PREVISTAS, AINDA NÃO LANÇADAS)
K4: =SUM(Tabela1[PAGO]) -> 0 | L4: =SUM(Tabela1[A_PAGAR]) -> 0 | W4: =SUM(Tabela2[TOTAL DO CONTRATO]) -> 0 | X4: =SUM(Tabela2[TOTAL APROVADO]) -> 0 | Y4: =SUM(Tabela2[TOTAL SALDO]) -> 0
B5: ATUALIZACAO | C5: EMPRESA | D5: OBRA | E5: ITEM_PL | F5: SERVICO | G5: INSUMO | H5: FORNECEDOR | I5: PROCESSO | J5: DATA_DE_PAGAMENTO | K5: PAGO | L5: A_PAGAR | M5: DATA_GERACAO | N5: CHAVE | P5: EMPRESA | Q5: OBRA | R5: SERVIÇO | S5: INSUMO | T5: FORNECEDOR | U5: ITEM PL | V5: CONTRATO | W5: TOTAL DO CONTRATO | X5: TOTAL APROVADO | Y5: TOTAL SALDO | AB5: ITEM | AC5: ALOCAÇÃO | AD5: VALOR PREVISTO
B6: 46244 | C6: 000 - EMPRESA EXEMPLO LTDA | D6: OBRA EXEMPLO - CUSTO DE OBRA | E6: 01.01.02.01 | F6: C18698 - BARRACÕES DE OBRA | G6: I19120 - MATERIAL DE APOIO | H6: 000 - FORNECEDOR EXEMPLO | I6: 46039 | J6: 46268 | K6: 0 | L6: 0 | M6: 46240 | N6: =_xlfn.CONCAT(Tabela1[[#This Row],[ITEM_PL]]," - ",MID(Tabela1[[#This Row],[SERVICO]],1,SEARCH(" ",Tabela1[[#This Row],[SERVICO]],1)-1)) -> 01.01.02.01 - C18698 | P6: 000 - EMPRESA EXEMPLO LTDA | Q6: OBRA EXEMPLO - CUSTO DE OBRA | R6: C17211 - INSTALAÇÕES DE CANTEIRO | S6: TC0351 - SERVICOS GERAIS | T6: 000 - FORNECEDOR EXEMPLO | U6: 01.01.02.07 | V6: 3 | W6: 0 | X6: 0 | Y6: 0
B7: 46244 | C7: 000 - EMPRESA EXEMPLO LTDA | D7: OBRA EXEMPLO - CUSTO DE OBRA | E7: 01.01.02.01 | F7: C18698 - BARRACÕES DE OBRA | G7: TC0351 - SERVICOS GERAIS | H7: 000 - FORNECEDOR EXEMPLO | I7: 46025 | J7: 46245 | K7: 0 | L7: 0 | M7: 46232 | N7: =_xlfn.CONCAT(Tabela1[[#This Row],[ITEM_PL]]," - ",MID(Tabela1[[#This Row],[SERVICO]],1,SEARCH(" ",Tabela1[[#This Row],[SERVICO]],1)-1)) -> 01.01.02.01 - C18698 | P7: 000 - EMPRESA EXEMPLO LTDA | Q7: OBRA EXEMPLO - CUSTO DE OBRA | R7: CSF7.04 - DEMOLIÇÃO. | S7: TC0351 - SERVICOS GERAIS | T7: 000 - FORNECEDOR EXEMPLO | U7: 01.02.00.03 | V7: 1 | W7: 0 | X7: 0 | Y7: 0
B8: 46244 | C8: 000 - EMPRESA EXEMPLO LTDA | D8: OBRA EXEMPLO - CUSTO DE OBRA | E8: 01.01.04.02 | F8: CO454 - GERENTE DE OBRA | G8: I19120 - MATERIAL DE APOIO | H8: 000 - FORNECEDOR EXEMPLO | I8: 46041 | J8: 46248 | K8: 0 | L8: 0 | M8: 46241 | N8: =_xlfn.CONCAT(Tabela1[[#This Row],[ITEM_PL]]," - ",MID(Tabela1[[#This Row],[SERVICO]],1,SEARCH(" ",Tabela1[[#This Row],[SERVICO]],1)-1)) -> 01.01.04.02 - CO454 | P8: 000 - EMPRESA EXEMPLO LTDA | Q8: OBRA EXEMPLO - CUSTO DE OBRA | R8: C00756 - GERENCIAMENTO DE OBRA | S8: I19849 - DESPESAS CONTABEIS | T8: 000 - FORNECEDOR EXEMPLO | U8: 01.04.03.01 | V8: 4 | W8: 0 | X8: 0 | Y8: 0
B9: 46244 | C9: 000 - EMPRESA EXEMPLO LTDA | D9: OBRA EXEMPLO - CUSTO DE OBRA | E9: 01.01.01.01 | F9: C18612 - SERVIÇO DE ELABORAÇÃO DE MANUAL DO PROPRIETÁRIO | G9: I38849 - SEGURO DE OBRA | H9: 000 - FORNECEDOR EXEMPLO | I9: 46060 | J9: 46232 | K9: 0 | L9: 0 | M9: 46232 | N9: =_xlfn.CONCAT(Tabela1[[#This Row],[ITEM_PL]]," - ",MID(Tabela1[[#This Row],[SERVICO]],1,SEARCH(" ",Tabela1[[#This Row],[SERVICO]],1)-1)) -> 01.01.01.01 - C18612 | P9: 000 - EMPRESA EXEMPLO LTDA | Q9: OBRA EXEMPLO - CUSTO DE OBRA | R9: C00756 - GERENCIAMENTO DE OBRA | S9: TC0351 - SERVICOS GERAIS | T9: 000 - FORNECEDOR EXEMPLO | U9: 01.04.03.01 | V9: 2 | W9: 0 | X9: 0 | Y9: 0
B10: 46244 | C10: 000 - EMPRESA EXEMPLO LTDA | D10: OBRA EXEMPLO - CUSTO DE OBRA | E10: 01.02.00.03 | F10: CSF7.04 - DEMOLIÇÃO. | G10: TC0351 - SERVICOS GERAIS | H10: 000 - FORNECEDOR EXEMPLO | I10: 46037 | J10: 46240 | K10: 0 | L10: 0 | M10: 46233 | N10: =_xlfn.CONCAT(Tabela1[[#This Row],[ITEM_PL]]," - ",MID(Tabela1[[#This Row],[SERVICO]],1,SEARCH(" ",Tabela1[[#This Row],[SERVICO]],1)-1)) -> 01.02.00.03 - CSF7.04
B11: 46244 | C11: 000 - EMPRESA EXEMPLO LTDA | D11: OBRA EXEMPLO - CUSTO DE OBRA | E11: 01.01.01.01 | F11: C18612 - SERVIÇO DE ELABORAÇÃO DE MANUAL DO PROPRIETÁRIO | G11: I38849 - SEGURO DE OBRA | H11: 000 - FORNECEDOR EXEMPLO | I11: 46088 | J11: 46261 | K11: 0 | L11: 0 | M11: 46232 | N11: =_xlfn.CONCAT(Tabela1[[#This Row],[ITEM_PL]]," - ",MID(Tabela1[[#This Row],[SERVICO]],1,SEARCH(" ",Tabela1[[#This Row],[SERVICO]],1)-1)) -> 01.01.01.01 - C18612
B12: 46244 | C12: 000 - EMPRESA EXEMPLO LTDA | D12: OBRA EXEMPLO - CUSTO DE OBRA | E12: 01.01.01.01 | F12: C18612 - SERVIÇO DE ELABORAÇÃO DE MANUAL DO PROPRIETÁRIO | G12: I38849 - SEGURO DE OBRA | H12: 000 - FORNECEDOR EXEMPLO | I12: 46119 | J12: 46293 | K12: 0 | L12: 0 | M12: 46232 | N12: =_xlfn.CONCAT(Tabela1[[#This Row],[ITEM_PL]]," - ",MID(Tabela1[[#This Row],[SERVICO]],1,SEARCH(" ",Tabela1[[#This Row],[SERVICO]],1)-1)) -> 01.01.01.01 - C18612
B13: 46244 | C13: 000 - EMPRESA EXEMPLO LTDA | D13: OBRA EXEMPLO - CUSTO DE OBRA | E13: 01.01.02.07 | F13: C17211 - INSTALAÇÕES DE CANTEIRO | G13: TC0351 - SERVICOS GERAIS | H13: 000 - FORNECEDOR EXEMPLO | I13: 46040 | J13: 46248 | K13: 0 | L13: 0 | M13: 46241 | N13: =_xlfn.CONCAT(Tabela1[[#This Row],[ITEM_PL]]," - ",MID(Tabela1[[#This Row],[SERVICO]],1,SEARCH(" ",Tabela1[[#This Row],[SERVICO]],1)-1)) -> 01.01.02.07 - C17211
B14: 46244 | C14: 000 - EMPRESA EXEMPLO LTDA | D14: OBRA EXEMPLO - CUSTO DE OBRA | E14: 01.02.00.03 | F14: CSF7.04 - DEMOLIÇÃO. | G14: I19120 - MATERIAL DE APOIO | H14: 000 - FORNECEDOR EXEMPLO | I14: 46038 | J14: 46247 | K14: 0 | L14: 0 | M14: 46239 | N14: =_xlfn.CONCAT(Tabela1[[#This Row],[ITEM_PL]]," - ",MID(Tabela1[[#This Row],[SERVICO]],1,SEARCH(" ",Tabela1[[#This Row],[SERVICO]],1)-1)) -> 01.02.00.03 - CSF7.04
B15: 46244 | C15: 000 - EMPRESA EXEMPLO LTDA | D15: OBRA EXEMPLO - CUSTO DE OBRA | E15: 01.01.01.01 | F15: C18612 - SERVIÇO DE ELABORAÇÃO DE MANUAL DO PROPRIETÁRIO | G15: I38849 - SEGURO DE OBRA | H15: 000 - FORNECEDOR EXEMPLO | I15: 46149 | J15: 46322 | K15: 0 | L15: 0 | M15: 46232 | N15: =_xlfn.CONCAT(Tabela1[[#This Row],[ITEM_PL]]," - ",MID(Tabela1[[#This Row],[SERVICO]],1,SEARCH(" ",Tabela1[[#This Row],[SERVICO]],1)-1)) -> 01.01.01.01 - C18612
